Workbook
Name _20_fev_03: #REF!
Name _28_nov_02: #REF!
Name _30_dez_02: #REF!
Name _fl_: [1]DADOS!#REF!
Name BANCO: #REF!
Name BANCO_DADOS: #REF!
Name CC: #REF!
Name CLASSIFICAÇÃO: #REF!
Name dados: #REF!
Name FAVORECIDO: #REF!
Name feriados: [2]Geral!$B$37:$H$50
Name GRUPO: #REF!
Name INST: [3]!Tabela5[INSTITUIÇÃO]
Name INSTITUICAO: OFFSET(PM!$L$13,0,0,'[4]BASE TP OPER'!$R$1)
Name INSTITUICAO: OFFSET(#REF!,0,0,'[4]BASE TP OPER'!$R$1)
Name Instituições: [5]!Tabela8[Instituição]
Name k_desgual: '[2]T Desiguais'!$C$6
Name libio_balboa: #REF!
Name Nao_Uniforme: '[4]NAO UNIFORME'!#REF!,'[4]NAO UNIFORME'!#REF!
Name S_N_U: '[4]NAO UNIFORME'!#REF!
Name SegmentaçãodeDados_BANCO: #N/A
Name SegmentaçãodeDados_BANCO11: #N/A
Name SegmentaçãodeDados_TIPO: #N/A
Name SegmentaçãodeDados_TIPO11: #N/A
Name SNUTI: '[4]NAO UNIFORME'!#REF!
Name SUB_TIPO: #REF!
Name TIPO: #REF!
Name wilma: #REF!

Sheet BASE
A1: PORTADOR | B1: STATUS | C1: SITUAÇÃO | D1: POSIÇÃO | E1: RECOMPRADO | F1: CARTÓRIO
A2: ALUFORCE | B2: A VENCER | C2: A VISTA | D2: LIQUIDADO | E2: A RECEBER | F2: FUNDO
A3: AUGURI | B3: VENCIDO | C3: CARTEIRA | D3: RECOMPRADO | E3: RECEBIDO | F3: ALUFORCE
A4: CAPITAL ANNEX | C4: DISPONÍVEL
A5: CONTINENTAL | C5: OPERADO
A6: DEL MONTE
A7: FAMA
A8: H8
A9: IGNIS
A10: ITAU
A11: LEPTA
A12: ONIX
A13: VALE RIO CLARO

Sheet RESUMO
B1: RESUMO CONTAS A RECEBER
R2: CARTORIO
B3: TOTAL GERAL | E3: =E11+J19+J21+J22+L19+N19 -> #VALUE! | G3: PARCEIRO | H3: A VENCER | I3: VENCIDO | J3: TOTAL | L3: LIQUIDADO | N3: RECOMPRADO | O3: A RECEBER | P3: RECEBIDO | R3: FUNDO | S3: ALUFORCE
B4: CHECK | E4: =FATURAMENTO!H5-RESUMO!E3 -> #VALUE! | G4: AUGURI | H4: =SUMIFS(FATURAMENTO!$H$8:$H$1048576,FATURAMENTO!$M$8:$M$1048576,RESUMO!$H$3,FATURAMENTO!$K$8:$K$1048576,RESUMO!G4) -> 150514.04 | I4: =SUMIFS(FATURAMENTO!$H$8:$H$1048576,FATURAMENTO!$M$8:$M$1048576,$I$3,FATURAMENTO!$K$8:$K$1048576,G4) -> 0 | J4: =H4+I4-N4 -> 150514.04 | L4: =SUMIFS(FATURAMENTO!$H$8:$H$1048576,FATURAMENTO!$M$8:$M$1048576,$L$3,FATURAMENTO!$K$8:$K$1048576,G4) -> 67217.11 | N4: =SUMIFS(FATURAMENTO!$H$8:$H$1048576,FATURAMENTO!$K$8:$K$1048576,RESUMO!$G4,FATURAMENTO!$O$8:$O$1048576,RESUMO!$N$3) -> 0 | O4: =SUMIFS(FATURAMENTO!$H$8:$H$1048576,FATURAMENTO!$K$8:$K$1048576,RESUMO!$G4,FATURAMENTO!$Q$8:$Q$1048576,RESUMO!$O$3) -> 0 | P4: =SUMIFS(FATURAMENTO!$H$8:$H$1048576,FATURAMENTO!$K$8:$K$1048576,RESUMO!$G4,FATURAMENTO!$Q$8:$Q$1048576,$P$3) -> 0 | R4: =SUMIFS(FATURAMENTO!$H$8:$H$1048576,FATURAMENTO!$K$8:$K$1048576,RESUMO!$G4,FATURAMENTO!$S$8:$S$1048576,RESUMO!$R$3) -> 0 | S4: =SUMIFS(FATURAMENTO!$H$8:$H$1048576,FATURAMENTO!$K$8:$K$1048576,RESUMO!$G4,FATURAMENTO!$S$8:$S$1048576,$S$3) -> 0
G5: CAPITAL ANNEX | H5: =SUMIFS(FATURAMENTO!$H$8:$H$1048576,FATURAMENTO!$M$8:$M$1048576,RESUMO!$H$3,FATURAMENTO!$K$8:$K$1048576,RESUMO!G5) -> 414150.34 | I5: =SUMIFS(FATURAMENTO!$H$8:$H$1048576,FATURAMENTO!$M$8:$M$1048576,$I$3,FATURAMENTO!$K$8:$K$1048576,G5) -> 4381.86 | J5: =H5+I5-N5 -> 418532.2 | L5: =SUMIFS(FATURAMENTO!$H$8:$H$1048576,FATURAMENTO!$M$8:$M$1048576,$L$3,FATURAMENTO!$K$8:$K$1048576,G5) -> 247856.98 | N5: =SUMIFS(FATURAMENTO!$H$8:$H$1048576,FATURAMENTO!$K$8:$K$1048576,RESUMO!$G5,FATURAMENTO!$O$8:$O$1048576,RESUMO!$N$3) -> 0 | O5: =SUMIFS(FATURAMENTO!$H$8:$H$1048576,FATURAMENTO!$K$8:$K$1048576,RESUMO!$G5,FATURAMENTO!$Q$8:$Q$1048576,RESUMO!$O$3) -> 0 | P5: =SUMIFS(FATURAMENTO!$H$8:$H$1048576,FATURAMENTO!$K$8:$K$1048576,RESUMO!$G5,FATURAMENTO!$Q$8:$Q$1048576,$P$3) -> 0 | R5: =SUMIFS(FATURAMENTO!$H$8:$H$1048576,FATURAMENTO!$K$8:$K$1048576,RESUMO!$G5,FATURAMENTO!$S$8:$S$1048576,RESUMO!$R$3) -> 0 | S5: =SUMIFS(FATURAMENTO!$H$8:$H$1048576,FATURAMENTO!$K$8:$K$1048576,RESUMO!$G5,FATURAMENTO!$S$8:$S$1048576,$S$3) -> 0
B6: DISPONÍVEL | G6: CONTINENTAL | H6: =SUMIFS(FATURAMENTO!$H$8:$H$1048576,FATURAMENTO!$M$8:$M$1048576,RESUMO!$H$3,FATURAMENTO!$K$8:$K$1048576,RESUMO!G6) -> 0 | I6: =SUMIFS(FATURAMENTO!$H$8:$H$1048576,FATURAMENTO!$M$8:$M$1048576,$I$3,FATURAMENTO!$K$8:$K$1048576,G6) -> 0 | J6: =H6+I6-N6 -> 0 | L6: =SUMIFS(FATURAMENTO!$H$8:$H$1048576,FATURAMENTO!$M$8:$M$1048576,$L$3,FATURAMENTO!$K$8:$K$1048576,G6) -> 0 | N6: =SUMIFS(FATURAMENTO!$H$8:$H$1048576,FATURAMENTO!$K$8:$K$1048576,RESUMO!$G6,FATURAMENTO!$O$8:$O$1048576,RESUMO!$N$3) -> 0 | O6: =SUMIFS(FATURAMENTO!$H$8:$H$1048576,FATURAMENTO!$K$8:$K$1048576,RESUMO!$G6,FATURAMENTO!$Q$8:$Q$1048576,RESUMO!$O$3) -> 0 | P6: =SUMIFS(FATURAMENTO!$H$8:$H$1048576,FATURAMENTO!$K$8:$K$1048576,RESUMO!$G6,FATURAMENTO!$Q$8:$Q$1048576,$P$3) -> 0 | R6: =SUMIFS(FATURAMENTO!$H$8:$H$1048576,FATURAMENTO!$K$8:$K$1048576,RESUMO!$G6,FATURAMENTO!$S$8:$S$1048576,RESUMO!$R$3) -> 0 | S6: =SUMIFS(FATURAMENTO!$H$8:$H$1048576,FATURAMENTO!$K$8:$K$1048576,RESUMO!$G6,FATURAMENTO!$S$8:$S$1048576,$S$3) -> 0
B7: EMPRESA | C7: NF | D7: F9 | E7: TOTAL | G7: DEL MONTE | H7: =SUMIFS(FATURAMENTO!$H$8:$H$1048576,FATURAMENTO!$M$8:$M$1048576,RESUMO!$H$3,FATURAMENTO!$K$8:$K$1048576,RESUMO!G7) -> 4364.1 | I7: =SUMIFS(FATURAMENTO!$H$8:$H$1048576,FATURAMENTO!$M$8:$M$1048576,$I$3,FATURAMENTO!$K$8:$K$1048576,G7) -> 27611 | J7: =H7+I7-N7 -> 31975.1 | L7: =SUMIFS(FATURAMENTO!$H$8:$H$1048576,FATURAMENTO!$M$8:$M$1048576,$L$3,FATURAMENTO!$K$8:$K$1048576,G7) -> 589422.07 | N7: =SUMIFS(FATURAMENTO!$H$8:$H$1048576,FATURAMENTO!$K$8:$K$1048576,RESUMO!$G7,FATURAMENTO!$O$8:$O$1048576,RESUMO!$N$3) -> 0 | O7: =SUMIFS(FATURAMENTO!$H$8:$H$1048576,FATURAMENTO!$K$8:$K$1048576,RESUMO!$G7,FATURAMENTO!$Q$8:$Q$1048576,RESUMO!$O$3) -> 0 | P7: =SUMIFS(FATURAMENTO!$H$8:$H$1048576,FATURAMENTO!$K$8:$K$1048576,RESUMO!$G7,FATURAMENTO!$Q$8:$Q$1048576,$P$3) -> 0 | R7: =SUMIFS(FATURAMENTO!$H$8:$H$1048576,FATURAMENTO!$K$8:$K$1048576,RESUMO!$G7,FATURAMENTO!$S$8:$S$1048576,RESUMO!$R$3) -> 36494 | S7: =SUMIFS(FATURAMENTO!$H$8:$H$1048576,FATURAMENTO!$K$8:$K$1048576,RESUMO!$G7,FATURAMENTO!$S$8:$S$1048576,$S$3) -> 0
B8: ALUFORCE | C8: =SUMIFS(FATURAMENTO!$H:$H,FATURAMENTO!$C:$C,RESUMO!C7,FATURAMENTO!$A:$A,RESUMO!B8,FATURAMENTO!$J:$J,RESUMO!$B$6) -> 0 | D8: =SUMIFS(FATURAMENTO!$H:$H,FATURAMENTO!$C:$C,RESUMO!D7,FATURAMENTO!$A:$A,B8,FATURAMENTO!$J:$J,RESUMO!$B$6) -> 0 | E8: =C8+D8 -> 0 | G8: FAMA | H8: =SUMIFS(FATURAMENTO!$H$8:$H$1048576,FATURAMENTO!$M$8:$M$1048576,RESUMO!$H$3,FATURAMENTO!$K$8:$K$1048576,RESUMO!G8) -> 790342.53 | I8: =SUMIFS(FATURAMENTO!$H$8:$H$1048576,FATURAMENTO!$M$8:$M$1048576,$I$3,FATURAMENTO!$K$8:$K$1048576,G8) -> 0 | J8: =H8+I8-N8 -> 790342.53 | L8: =SUMIFS(FATURAMENTO!$H$8:$H$1048576,FATURAMENTO!$M$8:$M$1048576,$L$3,FATURAMENTO!$K$8:$K$1048576,G8) -> 1387214.4 | N8: =SUMIFS(FATURAMENTO!$H$8:$H$1048576,FATURAMENTO!$K$8:$K$1048576,RESUMO!$G8,FATURAMENTO!$O$8:$O$1048576,RESUMO!$N$3) -> 0 | O8: =SUMIFS(FATURAMENTO!$H$8:$H$1048576,FATURAMENTO!$K$8:$K$1048576,RESUMO!$G8,FATURAMENTO!$Q$8:$Q$1048576,RESUMO!$O$3) -> 0 | P8: =SUMIFS(FATURAMENTO!$H$8:$H$1048576,FATURAMENTO!$K$8:$K$1048576,RESUMO!$G8,FATURAMENTO!$Q$8:$Q$1048576,$P$3) -> 0 | R8: =SUMIFS(FATURAMENTO!$H$8:$H$1048576,FATURAMENTO!$K$8:$K$1048576,RESUMO!$G8,FATURAMENTO!$S$8:$S$1048576,RESUMO!$R$3) -> 38628.76 | S8: =SUMIFS(FATURAMENTO!$H$8:$H$1048576,FATURAMENTO!$K$8:$K$1048576,RESUMO!$G8,FATURAMENTO!$S$8:$S$1048576,$S$3) -> 0
B9: ENERGY | C9: =SUMIFS(FATURAMENTO!$H:$H,FATURAMENTO!$C:$C,RESUMO!C8,FATURAMENTO!$A:$A,RESUMO!B9,FATURAMENTO!$J:$J,RESUMO!$B$6) -> 0 | D9: =SUMIFS(FATURAMENTO!$H:$H,FATURAMENTO!$C:$C,RESUMO!D8,FATURAMENTO!$A:$A,B9,FATURAMENTO!$J:$J,RESUMO!$B$6) -> 0 | E9: =C9+D9 -> 0 | G9: H8 | H9: =SUMIFS(FATURAMENTO!$H$8:$H$1048576,FATURAMENTO!$M$8:$M$1048576,RESUMO!$H$3,FATURAMENTO!$K$8:$K$1048576,RESUMO!G9) -> 404006.17 | I9: =SUMIFS(FATURAMENTO!$H$8:$H$1048576,FATURAMENTO!$M$8:$M$1048576,$I$3,FATURAMENTO!$K$8:$K$1048576,G9) -> 35045.41 | J9: =H9+I9-N9 -> 439051.58 | L9: =SUMIFS(FATURAMENTO!$H$8:$H$1048576,FATURAMENTO!$M$8:$M$1048576,$L$3,FATURAMENTO!$K$8:$K$1048576,G9) -> 380480.24 | N9: =SUMIFS(FATURAMENTO!$H$8:$H$1048576,FATURAMENTO!$K$8:$K$1048576,RESUMO!$G9,FATURAMENTO!$O$8:$O$1048576,RESUMO!$N$3) -> 0 | O9: =SUMIFS(FATURAMENTO!$H$8:$H$1048576,FATURAMENTO!$K$8:$K$1048576,RESUMO!$G9,FATURAMENTO!$Q$8:$Q$1048576,RESUMO!$O$3) -> 0 | P9: =SUMIFS(FATURAMENTO!$H$8:$H$1048576,FATURAMENTO!$K$8:$K$1048576,RESUMO!$G9,FATURAMENTO!$Q$8:$Q$1048576,$P$3) -> 0 | R9: =SUMIFS(FATURAMENTO!$H$8:$H$1048576,FATURAMENTO!$K$8:$K$1048576,RESUMO!$G9,FATURAMENTO!$S$8:$S$1048576,RESUMO!$R$3) -> 17192 | S9: =SUMIFS(FATURAMENTO!$H$8:$H$1048576,FATURAMENTO!$K$8:$K$1048576,RESUMO!$G9,FATURAMENTO!$S$8:$S$1048576,$S$3) -> 0
B10: LABOR | C10: =SUMIFS(FATURAMENTO!$H:$H,FATURAMENTO!$C:$C,RESUMO!C9,FATURAMENTO!$A:$A,RESUMO!B10,FATURAMENTO!$J:$J,RESUMO!$B$6) -> 0 | D10: =SUMIFS(FATURAMENTO!$H:$H,FATURAMENTO!$C:$C,RESUMO!D9,FATURAMENTO!$A:$A,B10,FATURAMENTO!$J:$J,RESUMO!$B$6) -> 0 | E10: =C10+D10 -> 0 | G10: KHAVA | H10: =SUMIFS(FATURAMENTO!$H$8:$H$1048576,FATURAMENTO!$M$8:$M$1048576,RESUMO!$H$3,FATURAMENTO!$K$8:$K$1048576,RESUMO!G10) -> 0 | I10: =SUMIFS(FATURAMENTO!$H$8:$H$1048576,FATURAMENTO!$M$8:$M$1048576,$I$3,FATURAMENTO!$K$8:$K$1048576,G10) -> 0 | J10: =H10+I10-N10 -> 0 | L10: =SUMIFS(FATURAMENTO!$H$8:$H$1048576,FATURAMENTO!$M$8:$M$1048576,$L$3,FATURAMENTO!$K$8:$K$1048576,G10) -> 0 | N10: =SUMIFS(FATURAMENTO!$H$8:$H$1048576,FATURAMENTO!$K$8:$K$1048576,RESUMO!$G10,FATURAMENTO!$O$8:$O$1048576,RESUMO!$N$3) -> 0 | O10: =SUMIFS(FATURAMENTO!$H$8:$H$1048576,FATURAMENTO!$K$8:$K$1048576,RESUMO!$G10,FATURAMENTO!$Q$8:$Q$1048576,RESUMO!$O$3) -> 0 | P10: =SUMIFS(FATURAMENTO!$H$8:$H$1048576,FATURAMENTO!$K$8:$K$1048576,RESUMO!$G10,FATURAMENTO!$Q$8:$Q$1048576,$P$3) -> 0 | R10: =SUMIFS(FATURAMENTO!$H$8:$H$1048576,FATURAMENTO!$K$8:$K$1048576,RESUMO!$G10,FATURAMENTO!$S$8:$S$1048576,RESUMO!$R$3) -> 0 | S10: =SUMIFS(FATURAMENTO!$H$8:$H$1048576,FATURAMENTO!$K$8:$K$1048576,RESUMO!$G10,FATURAMENTO!$S$8:$S$1048576,$S$3) -> 0
C11: =SUM(C8:C10) -> 0 | D11: =SUM(D8:D10) -> 0 | E11: =C11+D11 -> 0 | G11: LEPTA | H11: =SUMIFS(FATURAMENTO!$H$8:$H$1048576,FATURAMENTO!$M$8:$M$1048576,RESUMO!$H$3,FATURAMENTO!$K$8:$K$1048576,RESUMO!G11) -> 125131.28 | I11: =SUMIFS(FATURAMENTO!$H$8:$H$1048576,FATURAMENTO!$M$8:$M$1048576,$I$3,FATURAMENTO!$K$8:$K$1048576,G11) -> 0 | J11: =H11+I11-N11 -> 125131.28 | L11: =SUMIFS(FATURAMENTO!$H$8:$H$1048576,FATURAMENTO!$M$8:$M$1048576,$L$3,FATURAMENTO!$K$8:$K$1048576,G11) -> 345775 | N11: =SUMIFS(FATURAMENTO!$H$8:$H$1048576,FATURAMENTO!$K$8:$K$1048576,RESUMO!$G11,FATURAMENTO!$O$8:$O$1048576,RESUMO!$N$3) -> 0 | O11: =SUMIFS(FATURAMENTO!$H$8:$H$1048576,FATURAMENTO!$K$8:$K$1048576,RESUMO!$G11,FATURAMENTO!$Q$8:$Q$1048576,RESUMO!$O$3) -> 0 | P11: =SUMIFS(FATURAMENTO!$H$8:$H$1048576,FATURAMENTO!$K$8:$K$1048576,RESUMO!$G11,FATURAMENTO!$Q$8:$Q$1048576,$P$3) -> 0 | R11: =SUMIFS(FATURAMENTO!$H$8:$H$1048576,FATURAMENTO!$K$8:$K$1048576,RESUMO!$G11,FATURAMENTO!$S$8:$S$1048576,RESUMO!$R$3) -> 0 | S11: =SUMIFS(FATURAMENTO!$H$8:$H$1048576,FATURAMENTO!$K$8:$K$1048576,RESUMO!$G11,FATURAMENTO!$S$8:$S$1048576,$S$3) -> 0
G12: ONIX | H12: =SUMIFS(FATURAMENTO!$H$8:$H$1048576,FATURAMENTO!$M$8:$M$1048576,RESUMO!$H$3,FATURAMENTO!$K$8:$K$1048576,RESUMO!G12) -> 248763.27 | I12: =SUMIFS(FATURAMENTO!$H$8:$H$1048576,FATURAMENTO!$M$8:$M$1048576,$I$3,FATURAMENTO!$K$8:$K$1048576,G12) -> 0 | J12: =H12+I12-N12 -> 248763.27 | L12: =SUMIFS(FATURAMENTO!$H$8:$H$1048576,FATURAMENTO!$M$8:$M$1048576,$L$3,FATURAMENTO!$K$8:$K$1048576,G12) -> 26137.19 | N12: =SUMIFS(FATURAMENTO!$H$8:$H$1048576,FATURAMENTO!$K$8:$K$1048576,RESUMO!$G12,FATURAMENTO!$O$8:$O$1048576,RESUMO!$N$3) -> 0 | O12: =SUMIFS(FATURAMENTO!$H$8:$H$1048576,FATURAMENTO!$K$8:$K$1048576,RESUMO!$G12,FATURAMENTO!$Q$8:$Q$1048576,RESUMO!$O$3) -> 0 | P12: =SUMIFS(FATURAMENTO!$H$8:$H$1048576,FATURAMENTO!$K$8:$K$1048576,RESUMO!$G12,FATURAMENTO!$Q$8:$Q$1048576,$P$3) -> 0 | R12: =SUMIFS(FATURAMENTO!$H$8:$H$1048576,FATURAMENTO!$K$8:$K$1048576,RESUMO!$G12,FATURAMENTO!$S$8:$S$1048576,RESUMO!$R$3) -> 0 | S12: =SUMIFS(FATURAMENTO!$H$8:$H$1048576,FATURAMENTO!$K$8:$K$1048576,RESUMO!$G12,FATURAMENTO!$S$8:$S$1048576,$S$3) -> 0
G13: VALE RIO CLARO | H13: =SUMIFS(FATURAMENTO!$H$8:$H$1048576,FATURAMENTO!$M$8:$M$1048576,RESUMO!$H$3,FATURAMENTO!$K$8:$K$1048576,RESUMO!G13) -> 33557.59 | I13: =SUMIFS(FATURAMENTO!$H$8:$H$1048576,FATURAMENTO!$M$8:$M$1048576,$I$3,FATURAMENTO!$K$8:$K$1048576,G13) -> 22669.17 | J13: =H13+I13-N13 -> 38412.18 | L13: =SUMIFS(FATURAMENTO!$H$8:$H$1048576,FATURAMENTO!$M$8:$M$1048576,$L$3,FATURAMENTO!$K$8:$K$1048576,G13) -> 361255.92 | N13: =SUMIFS(FATURAMENTO!$H$8:$H$1048576,FATURAMENTO!$K$8:$K$1048576,RESUMO!$G13,FATURAMENTO!$O$8:$O$1048576,RESUMO!$N$3) -> 17814.58 | O13: =SUMIFS(FATURAMENTO!$H$8:$H$1048576,FATURAMENTO!$K$8:$K$1048576,RESUMO!$G13,FATURAMENTO!$Q$8:$Q$1048576,RESUMO!$O$3) -> 1333.33 | P13: =SUMIFS(FATURAMENTO!$H$8:$H$1048576,FATURAMENTO!$K$8:$K$1048576,RESUMO!$G13,FATURAMENTO!$Q$8:$Q$1048576,$P$3) -> 4540 | R13: =SUMIFS(FATURAMENTO!$H$8:$H$1048576,FATURAMENTO!$K$8:$K$1048576,RESUMO!$G13,FATURAMENTO!$S$8:$S$1048576,RESUMO!$R$3) -> 0 | S13: =SUMIFS(FATURAMENTO!$H$8:$H$1048576,FATURAMENTO!$K$8:$K$1048576,RESUMO!$G13,FATURAMENTO!$S$8:$S$1048576,$S$3) -> 1333.33
J14: =H14+I14 -> 0 | L14: =SUMIFS(FATURAMENTO!$H$8:$H$1048576,FATURAMENTO!$M$8:$M$1048576,$L$3,FATURAMENTO!$K$8:$K$1048576,G14) -> 0 | N14: =SUMIFS(FATURAMENTO!$H$8:$H$1048576,FATURAMENTO!$Q$8:$Q$1048576,RESUMO!$N$3,FATURAMENTO!$K$8:$K$1048576,RESUMO!$G14) -> 0
J17: =H17+I17 -> 0 | L17: =SUMIFS(FATURAMENTO!$H$8:$H$1048576,FATURAMENTO!$M$8:$M$1048576,$L$3,FATURAMENTO!$K$8:$K$1048576,G17) -> 0 | N17: =SUMIFS(FATURAMENTO!$H$8:$H$1048576,FATURAMENTO!$Q$8:$Q$1048576,RESUMO!$N$3,FATURAMENTO!$K$8:$K$1048576,RESUMO!$G17) -> 0
J18: =H18+I18 -> 0 | L18: =SUMIFS(FATURAMENTO!$H$8:$H$1048576,FATURAMENTO!$M$8:$M$1048576,$L$3,FATURAMENTO!$K$8:$K$1048576,G18) -> 0 | N18: =SUMIFS(FATURAMENTO!$H$8:$H$1048576,FATURAMENTO!$Q$8:$Q$1048576,RESUMO!$N$3,FATURAMENTO!$K$8:$K$1048576,RESUMO!$G18) -> 0
H19: =SUM(H4:H13) -> 2170829.3 | I19: =SUM(I4:I13) -> 89707.44 | J19: =SUM(J4:J13) -> 2242722.2 | L19: =SUM(L4:L13) -> 3405359 | N19: =SUM(N4:N18) -> 17814.58 | O19: =SUM(O4:O18) -> 1333.33 | P19: =SUM(P4:P18) -> 4540 | R19: =SUM(R4:R18) -> 92314.76 | S19: =SUM(S4:S18) -> 1333.33
G21: A VISTA | H21: =SUMIFS(FATURAMENTO!$H$20:$H$1048576,FATURAMENTO!$M$20:$M$1048576,RESUMO!$H$3,FATURAMENTO!$J$747:$J$1048576,RESUMO!G21) -> #VALUE! | I21: =SUMIFS(FATURAMENTO!$H$20:$H$1048576,FATURAMENTO!$M$20:$M$1048576,$I$3,FATURAMENTO!$J$747:$J$1048576,G21) -> #VALUE! | J21: =H21+I21 -> #VALUE! | L21: =SUMIFS(FATURAMENTO!$H$8:$H$1048576,FATURAMENTO!$M$8:$M$1048576,$L$3,FATURAMENTO!$K$8:$K$1048576,G21) -> 0
G22: CARTEIRA | H22: =SUMIFS(FATURAMENTO!$H$20:$H$1048576,FATURAMENTO!$M$20:$M$1048576,RESUMO!$H$3,FATURAMENTO!$J$747:$J$1048576,RESUMO!G22) -> #VALUE! | I22: =SUMIFS(FATURAMENTO!$H$20:$H$1048576,FATURAMENTO!$M$20:$M$1048576,$I$3,FATURAMENTO!$J$747:$J$1048576,G22) -> #VALUE! | J22: =H22+I22 -> #VALUE! | L22: =SUMIFS(FATURAMENTO!$H$8:$H$1048576,FATURAMENTO!$M$8:$M$1048576,$L$3,FATURAMENTO!$K$8:$K$1048576,G22) -> 0

Sheet FATURAMENTO
G5: TOTAL | H5: =SUM(H8:H1048576) -> 6418105.4 | I5: =TODAY() -> 46098
A6: DADOS DA NF | G6: SUBTOTAL | H6: =SUBTOTAL(9,H8:H1048576) -> 6418105.4 | I6: HOJE | K6: OPERAÇÕES FINANCEIRAS | N6: VENCIDO | O6: LIQUIDADO/RECOMPRADO | Q6: STATUS DA RECOMPRA
A7: EMPRESA | B7: EMISSÃO | C7: TIPO | D7: NFe | E7: P | F7: CLIENTE | G7: CNPJ | H7: VALOR P | I7: VCTO | J7: SITUAÇÃO | K7: PORTADOR | L7: DATA | M7: STATUS | N7: DIAS | O7: POSIÇÃO | P7: DATA2 | Q7: RECOMPRADO | R7: DATA3 | S7: CARTORIO | T7: OBSERVAÇÃO | U7: ACEITA TROCA FACTORY | V7: COMISSÁRIA
A8: ALUFORCE | B8: 45966 | C8: NF | D8: 165 | E8: 003/003 | F8: R.N.A METAIS E DISTRIBUIDORA LTDA | G8: 06.269.699/0001-76 | H8: 15586.66 | I8: 46031 | J8: OPERADO | K8: DEL MONTE | L8: 46003 | M8: =IF(Tabela4[[#This Row],[RECOMPRADO]]="RECEBIDO","LIQUIDADO",IF(O8="LIQUIDADO","LIQUIDADO",IF(I8<$I$5,"VENCIDO","A VENCER"))) -> LIQUIDADO | N8: =IF(Tabela4[[#This Row],[STATUS]]="LIQUIDADO","",Tabela4[[#This Row],[VCTO]]-$I$5) | O8: LIQUIDADO
A9: ENERGY | B9: 45971 | C9: NF | D9: 645 | E9: 002/003 | F9: 0003Z475 | G9: 20.590.831/0001-78 | H9: 1666.66 | I9: 46016 | J9: OPERADO | K9: BANCO | M9: =IF(Tabela4[[#This Row],[RECOMPRADO]]="RECEBIDO","LIQUIDADO",IF(O9="LIQUIDADO","LIQUIDADO",IF(I9<$I$5,"VENCIDO","A VENCER"))) -> LIQUIDADO | N9: =IF(Tabela4[[#This Row],[STATUS]]="LIQUIDADO","",Tabela4[[#This Row],[VCTO]]-$I$5) | O9: LIQUIDADO
A10: ENERGY | B10: 45971 | C10: F9 | D10: 645 | E10: 003/003 | F10: BELA CAAPORA EMPREENDIMENTOS IMOBILIARIOS SPE LTDA | G10: 20.590.831/0001-78 | H10: 1666.68 | I10: 46031 | J10: OPERADO | K10: H8 | L10: 46025 | M10: =IF(Tabela4[[#This Row],[RECOMPRADO]]="RECEBIDO","LIQUIDADO",IF(O10="LIQUIDADO","LIQUIDADO",IF(I10<$I$5,"VENCIDO","A VENCER"))) -> LIQUIDADO | N10: =IF(Tabela4[[#This Row],[STATUS]]="LIQUIDADO","",Tabela4[[#This Row],[VCTO]]-$I$5) | O10: LIQUIDADO
A11: ENERGY | B11: 45971 | C11: NF | D11: 645 | E11: 001/003 | F11: BELA CAAPORA EMPREENDIMENTOS IMOBILIARIOS SPE LTDA | G11: 20.590.831/0001-78 | H11: 3513.33 | I11: 46001 | J11: OPERADO | K11: BANCO | M11: =IF(Tabela4[[#This Row],[RECOMPRADO]]="RECEBIDO","LIQUIDADO",IF(O11="LIQUIDADO","LIQUIDADO",IF(I11<$I$5,"VENCIDO","A VENCER"))) -> LIQUIDADO | N11: =IF(Tabela4[[#This Row],[STATUS]]="LIQUIDADO","",Tabela4[[#This Row],[VCTO]]-$I$5) | O11: LIQUIDADO
A12: ENERGY | B12: 45971 | C12: NF | D12: 645 | E12: 003/003 | F12: BELA CAAPORA EMPREENDIMENTOS IMOBILIARIOS SPE LTDA | G12: 20.590.831/0001-78 | H12: 3446.66 | I12: 46031 | J12: OPERADO | K12: BANCO | M12: =IF(Tabela4[[#This Row],[RECOMPRADO]]="RECEBIDO","LIQUIDADO",IF(O12="LIQUIDADO","LIQUIDADO",IF(I12<$I$5,"VENCIDO","A VENCER"))) -> LIQUIDADO | N12: =IF(Tabela4[[#This Row],[STATUS]]="LIQUIDADO","",Tabela4[[#This Row],[VCTO]]-$I$5) | O12: LIQUIDADO
A13: ENERGY | B13: 45973 | C13: NF | D13: 653 | E13: 006/006 | F13: PONTO CERTO MATERIAIS ELETRIVOS E HIDRAULICOS LTDA | G13: 10.821.336/0001-79 | H13: 3035.85 | I13: 46030 | J13: OPERADO | K13: FAMA | L13: 46003 | M13: =IF(Tabela4[[#This Row],[RECOMPRADO]]="RECEBIDO","LIQUIDADO",IF(O13="LIQUIDADO","LIQUIDADO",IF(I13<$I$5,"VENCIDO","A VENCER"))) -> LIQUIDADO | N13: =IF(Tabela4[[#This Row],[STATUS]]="LIQUIDADO","",Tabela4[[#This Row],[VCTO]]-$I$5) | O13: LIQUIDADO
A14: ENERGY | B14: 45973 | C14: NF | D14: 652 | E14: 006/006 | F14: GLACAI INDUSTRIA DE SORVETES LTDA | G14: 30.062.482/0061-06 | H14: 2400 | I14: 46030 | J14: OPERADO | K14: FAMA | L14: 46003 | M14: =IF(Tabela4[[#This Row],[RECOMPRADO]]="RECEBIDO","LIQUIDADO",IF(O14="LIQUIDADO","LIQUIDADO",IF(I14<$I$5,"VENCIDO","A VENCER"))) -> LIQUIDADO | N14: =IF(Tabela4[[#This Row],[STATUS]]="LIQUIDADO","",Tabela4[[#This Row],[VCTO]]-$I$5) | O14: LIQUIDADO
A15: ENERGY | B15: 45975 | C15: NF | D15: 658 | E15: 005/005 | F15: ELETRICA BEL MATERIAIS ELETRICOS LTDA | G15: 58.246.059/0001-44 | H15: 2600.6 | I15: 46031 | J15: OPERADO | K15: VALE RIO CLARO | L15: 46027 | M15: =IF(Tabela4[[#This Row],[RECOMPRADO]]="RECEBIDO","LIQUIDADO",IF(O15="LIQUIDADO","LIQUIDADO",IF(I15<$I$5,"VENCIDO","A VENCER"))) -> LIQUIDADO | N15: =IF(Tabela4[[#This Row],[STATUS]]="LIQUIDADO","",Tabela4[[#This Row],[VCTO]]-$I$5) | O15: LIQUIDADO
A16: ALUFORCE | B16: 45978 | C16: NF | D16: 188 | E16: 003/003 | F16: EGIDIO & CAETANO - EXECUCOES ELETRICAS LTDA | G16: 23.899.714/0001-89 | H16: 10432.61 | I16: 46069 | J16: OPERADO | K16: FAMA | L16: 46003 | M16: =IF(Tabela4[[#This Row],[RECOMPRADO]]="RECEBIDO","LIQUIDADO",IF(O16="LIQUIDADO","LIQUIDADO",IF(I16<$I$5,"VENCIDO","A VENCER"))) -> LIQUIDADO | N16: =IF(Tabela4[[#This Row],[STATUS]]="LIQUIDADO","",Tabela4[[#This Row],[VCTO]]-$I$5) | O16: LIQUIDADO
A17: LABOR | B17: 45978 | C17: NF | D17: 4255 | E17: 006/006 | F17: J G COMERCIO DE MATERIAL ELETRICO LTDA | G17: 14.638.183/0001-80 | H17: 3225 | I17: 46044 | J17: OPERADO | K17: FAMA | L17: 46003 | M17: =IF(Tabela4[[#This Row],[RECOMPRADO]]="RECEBIDO","LIQUIDADO",IF(O17="LIQUIDADO","LIQUIDADO",IF(I17<$I$5,"VENCIDO","A VENCER"))) -> LIQUIDADO | N17: =IF(Tabela4[[#This Row],[STATUS]]="LIQUIDADO","",Tabela4[[#This Row],[VCTO]]-$I$5) | O17: LIQUIDADO
A18: LABOR | B18: 45978 | C18: NF | D18: 4259 | E18: 001/001 | F18: EXCEL DISTRIBUICAO DE MATERIAL ELETRICO LTDA | G18: 07.931.533/0001-36 | H18: 38628.76 | I18: 46066 | J18: OPERADO | K18: FAMA | L18: 46003 | M18: =IF(Tabela4[[#This Row],[RECOMPRADO]]="RECEBIDO","LIQUIDADO",IF(O18="LIQUIDADO","LIQUIDADO",IF(I18<$I$5,"VENCIDO","A VENCER"))) -> LIQUIDADO | N18: =IF(Tabela4[[#This Row],[STATUS]]="LIQUIDADO","",Tabela4[[#This Row],[VCTO]]-$I$5) | O18: LIQUIDADO | S18: FUNDO | T18: cliente informa que efetuou o pagamento no cartório porem consta como vencido no relatório
A19: ALUFORCE | B19: 45978 | C19: NF | D19: 191 | E19: 004/005 | F19: ANGELA A J BUSATTO & CIA LTDA | G19: 09.356.946/0001-60 | H19: 1854 | I19: 46031 | J19: OPERADO | K19: FAMA | L19: 46003 | M19: =IF(Tabela4[[#This Row],[RECOMPRADO]]="RECEBIDO","LIQUIDADO",IF(O19="LIQUIDADO","LIQUIDADO",IF(I19<$I$5,"VENCIDO","A VENCER"))) -> LIQUIDADO | N19: =IF(Tabela4[[#This Row],[STATUS]]="LIQUIDADO","",Tabela4[[#This Row],[VCTO]]-$I$5) | O19: LIQUIDADO
A20: LABOR | B20: 45978 | C20: NF | D20: 4255 | E20: 005/006 | F20: J G COMERCIO DE MATERIAL ELETRICO LTDA | G20: 14.638.183/0001-80 | H20: 3225 | I20: 46037 | J20: OPERADO | K20: FAMA | L20: 46003 | M20: =IF(Tabela4[[#This Row],[RECOMPRADO]]="RECEBIDO","LIQUIDADO",IF(O20="LIQUIDADO","LIQUIDADO",IF(I20<$I$5,"VENCIDO","A VENCER"))) -> LIQUIDADO | N20: =IF(Tabela4[[#This Row],[STATUS]]="LIQUIDADO","",Tabela4[[#This Row],[VCTO]]-$I$5) | O20: LIQUIDADO
A21: LABOR | B21: 45978 | C21: NF | D21: 4255 | E21: 004/006 | F21: J G COMERCIO DE MATERIAL ELETRICO LTDA | G21: 14.638.183/0001-80 | H21: 3225 | I21: 46030 | J21: OPERADO | K21: FAMA | L21: 46003 | M21: =IF(Tabela4[[#This Row],[RECOMPRADO]]="RECEBIDO","LIQUIDADO",IF(O21="LIQUIDADO","LIQUIDADO",IF(I21<$I$5,"VENCIDO","A VENCER"))) -> LIQUIDADO | N21: =IF(Tabela4[[#This Row],[STATUS]]="LIQUIDADO","",Tabela4[[#This Row],[VCTO]]-$I$5) | O21: LIQUIDADO
A22: LABOR | B22: 45978 | C22: NF | D22: 4256 | E22: 004/004 | F22: TOZZI MATERIAIS ELETRICOS LTDA | G22: 40.202.099/0001-29 | H22: 2242.5 | I22: 46031 | J22: OPERADO | K22: FAMA | L22: 46003 | M22: =IF(Tabela4[[#This Row],[RECOMPRADO]]="RECEBIDO","LIQUIDADO",IF(O22="LIQUIDADO","LIQUIDADO",IF(I22<$I$5,"VENCIDO","A VENCER"))) -> LIQUIDADO | N22: =IF(Tabela4[[#This Row],[STATUS]]="LIQUIDADO","",Tabela4[[#This Row],[VCTO]]-$I$5) | O22: LIQUIDADO
A23: LABOR | B23: 45978 | C23: NF | D23: 4258 | E23: 004/004 | F23: D F TOFFOLI MATERIAL ELETRICO LTDA | G23: 28.164.842/0001-06 | H23: 1751.25 | I23: 46031 | J23: OPERADO | K23: FAMA | L23: 46003 | M23: =IF(Tabela4[[#This Row],[RECOMPRADO]]="RECEBIDO","LIQUIDADO",IF(O23="LIQUIDADO","LIQUIDADO",IF(I23<$I$5,"VENCIDO","A VENCER"))) -> LIQUIDADO | N23: =IF(Tabela4[[#This Row],[STATUS]]="LIQUIDADO","",Tabela4[[#This Row],[VCTO]]-$I$5) | O23: LIQUIDADO
A24: LABOR | B24: 45978 | C24: NF | D24: 4253 | E24: 005/005 | F24: RDM CAMPINAS COMERCIO DE MATERIAIS ELETRICOS LTDA | G24: 40.919.972/0001-07 | H24: 1880 | I24: 46034 | J24: OPERADO | K24: FAMA | L24: 46003 | M24: =IF(Tabela4[[#This Row],[RECOMPRADO]]="RECEBIDO","LIQUIDADO",IF(O24="LIQUIDADO","LIQUIDADO",IF(I24<$I$5,"VENCIDO","A VENCER"))) -> LIQUIDADO | N24: =IF(Tabela4[[#This Row],[STATUS]]="LIQUIDADO","",Tabela4[[#This Row],[VCTO]]-$I$5) | O24: LIQUIDADO
A25: LABOR | B25: 45978 | C25: NF | D25: 4251 | E25: 005/005 | F25: SUPER FIO LTDA | G25: 57.231.501/0001-04 | H25: 1064 | I25: 46034 | J25: OPERADO | K25: FAMA | L25: 46003 | M25: =IF(Tabela4[[#This Row],[RECOMPRADO]]="RECEBIDO","LIQUIDADO",IF(O25="LIQUIDADO","LIQUIDADO",IF(I25<$I$5,"VENCIDO","A VENCER"))) -> LIQUIDADO | N25: =IF(Tabela4[[#This Row],[STATUS]]="LIQUIDADO","",Tabela4[[#This Row],[VCTO]]-$I$5) | O25: LIQUIDADO
A26: ALUFORCE | B26: 45978 | C26: NF | D26: 188 | E26: 002/003 | F26: EGIDIO & CAETANO - EXECUCOES ELETRICAS LTDA | G26: 23.899.714/0001-89 | H26: 10432.62 | I26: 46039 | J26: OPERADO | K26: FAMA | L26: 46003 | M26: =IF(Tabela4[[#This Row],[RECOMPRADO]]="RECEBIDO","LIQUIDADO",IF(O26="LIQUIDADO","LIQUIDADO",IF(I26<$I$5,"VENCIDO","A VENCER"))) -> LIQUIDADO | N26: =IF(Tabela4[[#This Row],[STATUS]]="LIQUIDADO","",Tabela4[[#This Row],[VCTO]]-$I$5) | O26: LIQUIDADO
A27: ALUFORCE | B27: 45978 | C27: NF | D27: 191 | E27: 005/005 | F27: ANGELA A J BUSATTO & CIA LTDA | G27: 09.356.946/0001-60 | H27: 1854 | I27: 46038 | J27: OPERADO | K27: FAMA | L27: 46003 | M27: =IF(Tabela4[[#This Row],[RECOMPRADO]]="RECEBIDO","LIQUIDADO",IF(O27="LIQUIDADO","LIQUIDADO",IF(I27<$I$5,"VENCIDO","A VENCER"))) -> LIQUIDADO | N27: =IF(Tabela4[[#This Row],[STATUS]]="LIQUIDADO","",Tabela4[[#This Row],[VCTO]]-$I$5) | O27: LIQUIDADO
A28: ALUFORCE | B28: 45980 | C28: NF | D28: 194 | E28: 002/003 | F28: COMERCIAL MARTINS LTDA | G28: 20.891.953/0001-02 | H28: 2006.75 | I28: 46042 | J28: OPERADO | K28: H8 | L28: 46025 | M28: =IF(Tabela4[[#This Row],[RECOMPRADO]]="RECEBIDO","LIQUIDADO",IF(O28="LIQUIDADO","LIQUIDADO",IF(I28<$I$5,"VENCIDO","A VENCER"))) -> LIQUIDADO | N28: =IF(Tabela4[[#This Row],[STATUS]]="LIQUIDADO","",Tabela4[[#This Row],[VCTO]]-$I$5) | O28: LIQUIDADO
A29: ALUFORCE | B29: 45980 | C29: NF | D29: 194 | E29: 003/003 | F29: COMERCIAL MARTINS LTDA | G29: 20.891.953/0001-02 | H29: 2006.75 | I29: 46072 | J29: OPERADO | K29: H8 | L29: 46025 | M29: =IF(Tabela4[[#This Row],[RECOMPRADO]]="RECEBIDO","LIQUIDADO",IF(O29="LIQUIDADO","LIQUIDADO",IF(I29<$I$5,"VENCIDO","A VENCER"))) -> LIQUIDADO | N29: =IF(Tabela4[[#This Row],[STATUS]]="LIQUIDADO","",Tabela4[[#This Row],[VCTO]]-$I$5) | O29: LIQUIDADO
A30: ALUFORCE | B30: 45980 | C30: F9 | D30: 194 | E30: 002/003 | F30: COMERCIAL MARTINS LTDA | G30: 20.891.953/0001-02 | H30: 2006.75 | I30: 46042 | J30: OPERADO | K30: H8 | L30: 46025 | M30: =IF(Tabela4[[#This Row],[RECOMPRADO]]="RECEBIDO","LIQUIDADO",IF(O30="LIQUIDADO","LIQUIDADO",IF(I30<$I$5,"VENCIDO","A VENCER"))) -> LIQUIDADO | N30: =IF(Tabela4[[#This Row],[STATUS]]="LIQUIDADO","",Tabela4[[#This Row],[VCTO]]-$I$5) | O30: LIQUIDADO
A31: ALUFORCE | B31: 45980 | C31: F9 | D31: 194 | E31: 003/003 | F31: COMERCIAL MARTINS LTDA | G31: 20.891.953/0001-02 | H31: 2006.75 | I31: 46072 | J31: OPERADO | K31: H8 | L31: 46025 | M31: =IF(Tabela4[[#This Row],[RECOMPRADO]]="RECEBIDO","LIQUIDADO",IF(O31="LIQUIDADO","LIQUIDADO",IF(I31<$I$5,"VENCIDO","A VENCER"))) -> LIQUIDADO | N31: =IF(Tabela4[[#This Row],[STATUS]]="LIQUIDADO","",Tabela4[[#This Row],[VCTO]]-$I$5) | O31: LIQUIDADO
A32: LABOR | B32: 45980 | C32: NF | D32: 4261 | E32: 003/003 | F32: CORREIA ATACADO MATERIAL ELETRICO LTDA | G32: 07.453.496/0001-06 | H32: 3444 | I32: 46042 | J32: OPERADO | K32: FAMA | L32: 46003 | M32: =IF(Tabela4[[#This Row],[RECOMPRADO]]="RECEBIDO","LIQUIDADO",IF(O32="LIQUIDADO","LIQUIDADO",IF(I32<$I$5,"VENCIDO","A VENCER"))) -> LIQUIDADO | N32: =IF(Tabela4[[#This Row],[STATUS]]="LIQUIDADO","",Tabela4[[#This Row],[VCTO]]-$I$5) | O32: LIQUIDADO
A33: LABOR | B33: 45980 | C33: NF | D33: 4262 | E33: 001/001 | F33: EXCEL DISTRIBUICAO DE MATERIAL ELETRICO LTDA | G33: 07.931.533/0001-36 | H33: 4151.6 | I33: 46066 | J33: OPERADO | K33: FAMA | L33: 46003 | M33: =IF(Tabela4[[#This Row],[RECOMPRADO]]="RECEBIDO","LIQUIDADO",IF(O33="LIQUIDADO","LIQUIDADO",IF(I33<$I$5,"VENCIDO","A VENCER"))) -> LIQUIDADO | N33: =IF(Tabela4[[#This Row],[STATUS]]="LIQUIDADO","",Tabela4[[#This Row],[VCTO]]-$I$5) | O33: LIQUIDADO | T33: prorrogada
A34: LABOR | B34: 45980 | C34: NF | D34: 4260 | E34: 001 | F34: JULIO CESAR F SOUSA SERVICOS LTDA | G34: 46.864.361/0001-87 | H34: 5875 | I34: 46012 | J34: CARTEIRA | K34: ALUFORCE | L34: 46052 | M34: =IF(Tabela4[[#This Row],[RECOMPRADO]]="RECEBIDO","LIQUIDADO",IF(O34="LIQUIDADO","LIQUIDADO",IF(I34<$I$5,"VENCIDO","A VENCER"))) -> VENCIDO | N34: =IF(Tabela4[[#This Row],[STATUS]]="LIQUIDADO","",Tabela4[[#This Row],[VCTO]]-$I$5) -> -86 | O34: RECOMPRADO | P34: 46052 | S34: FUNDO | T34: juridico
A35: LABOR | B35: 45980 | C35: NF | D35: 4260 | E35: 002 | F35: JULIO CESAR F SOUSA SERVICOS LTDA | G35: 46.864.361/0001-87 | H35: 5875 | I35: 46027 | J35: CARTEIRA | K35: ALUFORCE | L35: 46052 | M35: =IF(Tabela4[[#This Row],[RECOMPRADO]]="RECEBIDO","LIQUIDADO",IF(O35="LIQUIDADO","LIQUIDADO",IF(I35<$I$5,"VENCIDO","A VENCER"))) -> VENCIDO | N35: =IF(Tabela4[[#This Row],[STATUS]]="LIQUIDADO","",Tabela4[[#This Row],[VCTO]]-$I$5) -> -71 | O35: RECOMPRADO | P35: 46052 | S35: FUNDO | T35: juridico
A36: LABOR | B36: 45980 | C36: NF | D36: 4260 | E36: 003 | F36: JULIO CESAR F SOUSA SERVICOS LTDA | G36: 46.864.361/0001-87 | H36: 5875 | I36: 46042 | J36: CARTEIRA | K36: ALUFORCE | L36: 46052 | M36: =IF(Tabela4[[#This Row],[RECOMPRADO]]="RECEBIDO","LIQUIDADO",IF(O36="LIQUIDADO","LIQUIDADO",IF(I36<$I$5,"VENCIDO","A VENCER"))) -> VENCIDO | N36: =IF(Tabela4[[#This Row],[STATUS]]="LIQUIDADO","",Tabela4[[#This Row],[VCTO]]-$I$5) -> -56 | O36: RECOMPRADO | P36: 46052 | S36: FUNDO | T36: juridico
A37: LABOR | B37: 45985 | C37: NF | D37: 4264 | E37: 005/005 | F37: PETROLLUZ MATERIAIS ELETRICOS LTDA | G37: 02.493.174/0001-69 | H37: 2028 | I37: 46043 | J37: OPERADO | K37: H8 | L37: 46025 | M37: =IF(Tabela4[[#This Row],[RECOMPRADO]]="RECEBIDO","LIQUIDADO",IF(O37="LIQUIDADO","LIQUIDADO",IF(I37<$I$5,"VENCIDO","A VENCER"))) -> LIQUIDADO | N37: =IF(Tabela4[[#This Row],[STATUS]]="LIQUIDADO","",Tabela4[[#This Row],[VCTO]]-$I$5) | O37: LIQUIDADO
A38: LABOR | B38: 45985 | C38: NF | D38: 4264 | E38: 003/005 | F38: PETROLLUZ MATERIAIS ELETRICOS LTDA | G38: 02.493.174/0001-69 | H38: 2028 | I38: 46029 | J38: OPERADO | K38: H8 | L38: 46025 | M38: =IF(Tabela4[[#This Row],[RECOMPRADO]]="RECEBIDO","LIQUIDADO",IF(O38="LIQUIDADO","LIQUIDADO",IF(I38<$I$5,"VENCIDO","A VENCER"))) -> LIQUIDADO | N38: =IF(Tabela4[[#This Row],[STATUS]]="LIQUIDADO","",Tabela4[[#This Row],[VCTO]]-$I$5) | O38: LIQUIDADO
A39: LABOR | B39: 45985 | C39: NF | D39: 4264 | E39: 004/005 | F39: PETROLLUZ MATERIAIS ELETRICOS LTDA | G39: 02.493.174/0001-69 | H39: 2028 | I39: 46036 | J39: OPERADO | K39: H8 | L39: 46025 | M39: =IF(Tabela4[[#This Row],[RECOMPRADO]]="RECEBIDO","LIQUIDADO",IF(O39="LIQUIDADO","LIQUIDADO",IF(I39<$I$5,"VENCIDO","A VENCER"))) -> LIQUIDADO | N39: =IF(Tabela4[[#This Row],[STATUS]]="LIQUIDADO","",Tabela4[[#This Row],[VCTO]]-$I$5) | O39: LIQUIDADO
A40: LABOR | B40: 45986 | C40: NF | D40: 4265 | E40: 005/005 | F40: ELETROFLAVIO COMERCIAL ELETRICA LTDA | G40: 24.616.915/0001-94 | H40: 4152 | I40: 46044 | J40: OPERADO | K40: DEL MONTE | L40: 46003 | M40: =IF(Tabela4[[#This Row],[RECOMPRADO]]="RECEBIDO","LIQUIDADO",IF(O40="LIQUIDADO","LIQUIDADO",IF(I40<$I$5,"VENCIDO","A VENCER"))) -> LIQUIDADO | N40: =IF(Tabela4[[#This Row],[STATUS]]="LIQUIDADO","",Tabela4[[#This Row],[VCTO]]-$I$5) | O40: LIQUIDADO
A41: ALUFORCE | B41: 45986 | C41: NF | D41: 201 | E41: 003/004 | F41: GASPARZINHO DISTRIBUIDORA DE MATERIAIS ELETRICOS LTDA | G41: 2.042.020/0001-50 | H41: 1312.5 | I41: 46030 | J41: OPERADO | K41: H8 | L41: 46025 | M41: =IF(Tabela4[[#This Row],[RECOMPRADO]]="RECEBIDO","LIQUIDADO",IF(O41="LIQUIDADO","LIQUIDADO",IF(I41<$I$5,"VENCIDO","A VENCER"))) -> LIQUIDADO | N41: =IF(Tabela4[[#This Row],[STATUS]]="LIQUIDADO","",Tabela4[[#This Row],[VCTO]]-$I$5) | O41: LIQUIDADO
A42: ALUFORCE | B42: 45986 | C42: F9 | D42: 201 | E42: 003/004 | F42: GASPARZINHO DISTRIBUIDORA DE MATERIAIS ELETRICOS LTDA | G42: 2.042.020/0001-50 | H42: 1312.5 | I42: 46030 | J42: OPERADO | K42: H8 | L42: 46025 | M42: =IF(Tabela4[[#This Row],[RECOMPRADO]]="RECEBIDO","LIQUIDADO",IF(O42="LIQUIDADO","LIQUIDADO",IF(I42<$I$5,"VENCIDO","A VENCER"))) -> LIQUIDADO | N42: =IF(Tabela4[[#This Row],[STATUS]]="LIQUIDADO","",Tabela4[[#This Row],[VCTO]]-$I$5) | O42: LIQUIDADO
A43: LABOR | B43: 45986 | C43: NF | D43: 4265 | E43: 003/005 | F43: ELETROFLAVIO COMERCIAL ELETRICA LTDA | G43: 24.616.915/0001-94 | H43: 4152 | I43: 46030 | J43: OPERADO | K43: DEL MONTE | L43: 46003 | M43: =IF(Tabela4[[#This Row],[RECOMPRADO]]="RECEBIDO","LIQUIDADO",IF(O43="LIQUIDADO","LIQUIDADO",IF(I43<$I$5,"VENCIDO","A VENCER"))) -> LIQUIDADO | N43: =IF(Tabela4[[#This Row],[STATUS]]="LIQUIDADO","",Tabela4[[#This Row],[VCTO]]-$I$5) | O43: LIQUIDADO
A44: ENERGY | B44: 45986 | C44: NF | D44: 666 | E44: 001/003 | F44: ELIAS HUNGRIA DA CRUZ DE WENCESLAU GUIMARAES | G44: 15511415000105 | H44: 1075 | I44: 46015 | J44: OPERADO | K44: DEL MONTE | L44: 46003 | M44: =IF(Tabela4[[#This Row],[RECOMPRADO]]="RECEBIDO","LIQUIDADO",IF(O44="LIQUIDADO","LIQUIDADO",IF(I44<$I$5,"VENCIDO","A VENCER"))) -> VENCIDO | N44: =IF(Tabela4[[#This Row],[STATUS]]="LIQUIDADO","",Tabela4[[#This Row],[VCTO]]-$I$5) -> -83 | S44: FUNDO | T44: Em contato com senhor Elias o mesmo informa que esta aguardando o valor atualizado pelo cartório para efetuar o pagamento
...

Sheet DISPONÍVEL
A1: 3
D5: DISPONÍVEL
D6: EMPRESA | E6: NF | F6: F9 | G6: TOTAL
D7: ALUFORCE | E7: =SUMIFS(FATURAMENTO!$H:$H,FATURAMENTO!$C:$C,DISPONÍVEL!E6,FATURAMENTO!$A:$A,DISPONÍVEL!D7,FATURAMENTO!$J:$J,DISPONÍVEL!$D$5) -> 0 | F7: =SUMIFS(FATURAMENTO!$H:$H,FATURAMENTO!$C:$C,DISPONÍVEL!F6,FATURAMENTO!$A:$A,D7,FATURAMENTO!$J:$J,DISPONÍVEL!$D$5) -> 0 | G7: =E7+F7 -> 0
D8: ENERGY | E8: =SUMIFS(FATURAMENTO!$H:$H,FATURAMENTO!$C:$C,E6,FATURAMENTO!$A:$A,DISPONÍVEL!D8,FATURAMENTO!$J:$J,DISPONÍVEL!$D$5) -> 0 | F8: =SUMIFS(FATURAMENTO!$H:$H,FATURAMENTO!$C:$C,F6,FATURAMENTO!$A:$A,D8,FATURAMENTO!$J:$J,DISPONÍVEL!$D$5) -> 0 | G8: =E8+F8 -> 0
D9: LABOR | E9: =SUMIFS(FATURAMENTO!$H:$H,FATURAMENTO!$C:$C,E6,FATURAMENTO!$A:$A,DISPONÍVEL!D9,FATURAMENTO!$J:$J,DISPONÍVEL!$D$5) -> 0 | F9: =SUMIFS(FATURAMENTO!$H:$H,FATURAMENTO!$C:$C,F6,FATURAMENTO!$A:$A,D9,FATURAMENTO!$J:$J,DISPONÍVEL!$D$5) -> 0 | G9: =E9+F9 -> 0
E10: =SUM(E7:E9) -> 0 | F10: =SUM(F7:F9) -> 0 | G10: =E10+F10 -> 0

Sheet A RECEBER
D5: POSIÇÃO DOS FUNDOS/FIDCS
D6: PARCEIRO | E6: A VENCER | F6: VENCIDO | G6: TOTAL | I6: LIQUIDADO
D8: A VISTA | E8: =SUMIFS(FATURAMENTO!$H$8:$H$1048576,FATURAMENTO!$M$8:$M$1048576,'A RECEBER'!E$6,FATURAMENTO!$J$8:$J$1048576,'A RECEBER'!D8) -> 0 | F8: =SUMIFS(FATURAMENTO!$H$8:$H$1048576,FATURAMENTO!$M$8:$M$1048576,'A RECEBER'!F$6,FATURAMENTO!$J$8:$J$1048576,D8) -> 44000 | G8: =E8+F8 -> 44000 | I8: =SUMIFS(FATURAMENTO!$H$8:$H$1048576,FATURAMENTO!$M$8:$M$1048576,'A RECEBER'!I$6,FATURAMENTO!$J$8:$J$1048576,D8) -> 114119.24
D9: CARTEIRA | E9: =SUMIFS(FATURAMENTO!$H$8:$H$1048576,FATURAMENTO!$M$8:$M$1048576,'A RECEBER'!E$6,FATURAMENTO!$J$8:$J$1048576,'A RECEBER'!D9) -> 12405.01 | F9: =SUMIFS(FATURAMENTO!$H$8:$H$1048576,FATURAMENTO!$M$8:$M$1048576,'A RECEBER'!F$6,FATURAMENTO!$J$8:$J$1048576,D9) -> 24402.5 | G9: =E9+F9 -> 36807.51 | I9: =SUMIFS(FATURAMENTO!$H$8:$H$1048576,FATURAMENTO!$M$8:$M$1048576,'A RECEBER'!I$6,FATURAMENTO!$J$8:$J$1048576,D9) -> 33993.15

Sheet DIARIO
B4: CONTAS A RECEBER - DIÁRIO | F4: =D7+E7-FATURAMENTO!H5 -> -3653281.9
B7: HOJE | C7: VALOR | D7: =SUM(D9:D373) -> 2598752.5 | E7: =SUM(E9:E373) -> 166071.02
B8: =TODAY() -> 46098 | C8: DATA | D8: A VENCER | E8: VENCIDO
B9: =TEXT(C9,"dddd") -> quinta-feira | C9: 46023 | D9: =SUMIFS(FATURAMENTO!$H$8:$H$1048576,FATURAMENTO!$M$8:$M$1048576,DIARIO!D$8,FATURAMENTO!$I$8:$I$1048576,DIARIO!C9) -> 0 | E9: =SUMIFS(FATURAMENTO!$H$8:$H$1048576,FATURAMENTO!$M$8:$M$1048576,DIARIO!E$8,FATURAMENTO!$I$8:$I$1048576,C9) -> 0
B10: =TEXT(C10,"dddd") -> sexta-feira | C10: 46024 | D10: =SUMIFS(FATURAMENTO!$H$8:$H$1048576,FATURAMENTO!$M$8:$M$1048576,DIARIO!D$8,FATURAMENTO!$I$8:$I$1048576,DIARIO!C10) -> 0 | E10: =SUMIFS(FATURAMENTO!$H$8:$H$1048576,FATURAMENTO!$M$8:$M$1048576,DIARIO!E$8,FATURAMENTO!$I$8:$I$1048576,C10) -> 0
B11: =TEXT(C11,"dddd") -> sábado | C11: 46025 | D11: =SUMIFS(FATURAMENTO!$H$8:$H$1048576,FATURAMENTO!$M$8:$M$1048576,DIARIO!D$8,FATURAMENTO!$I$8:$I$1048576,DIARIO!C11) -> 0 | E11: =SUMIFS(FATURAMENTO!$H$8:$H$1048576,FATURAMENTO!$M$8:$M$1048576,DIARIO!E$8,FATURAMENTO!$I$8:$I$1048576,C11) -> 0
B12: =TEXT(C12,"dddd") -> domingo | C12: 46026 | D12: =SUMIFS(FATURAMENTO!$H$8:$H$1048576,FATURAMENTO!$M$8:$M$1048576,DIARIO!D$8,FATURAMENTO!$I$8:$I$1048576,DIARIO!C12) -> 0 | E12: =SUMIFS(FATURAMENTO!$H$8:$H$1048576,FATURAMENTO!$M$8:$M$1048576,DIARIO!E$8,FATURAMENTO!$I$8:$I$1048576,C12) -> 0
B13: =TEXT(C13,"dddd") -> segunda-feira | C13: 46027 | D13: =SUMIFS(FATURAMENTO!$H$8:$H$1048576,FATURAMENTO!$M$8:$M$1048576,DIARIO!D$8,FATURAMENTO!$I$8:$I$1048576,DIARIO!C13) -> 0 | E13: =SUMIFS(FATURAMENTO!$H$8:$H$1048576,FATURAMENTO!$M$8:$M$1048576,DIARIO!E$8,FATURAMENTO!$I$8:$I$1048576,C13) -> 5875
B14: =TEXT(C14,"dddd") -> terça-feira | C14: 46028 | D14: =SUMIFS(FATURAMENTO!$H$8:$H$1048576,FATURAMENTO!$M$8:$M$1048576,DIARIO!D$8,FATURAMENTO!$I$8:$I$1048576,DIARIO!C14) -> 0 | E14: =SUMIFS(FATURAMENTO!$H$8:$H$1048576,FATURAMENTO!$M$8:$M$1048576,DIARIO!E$8,FATURAMENTO!$I$8:$I$1048576,C14) -> 0
B15: =TEXT(C15,"dddd") -> quarta-feira | C15: 46029 | D15: =SUMIFS(FATURAMENTO!$H$8:$H$1048576,FATURAMENTO!$M$8:$M$1048576,DIARIO!D$8,FATURAMENTO!$I$8:$I$1048576,DIARIO!C15) -> 0 | E15: =SUMIFS(FATURAMENTO!$H$8:$H$1048576,FATURAMENTO!$M$8:$M$1048576,DIARIO!E$8,FATURAMENTO!$I$8:$I$1048576,C15) -> 1075
B16: =TEXT(C16,"dddd") -> quinta-feira | C16: 46030 | D16: =SUMIFS(FATURAMENTO!$H$8:$H$1048576,FATURAMENTO!$M$8:$M$1048576,DIARIO!D$8,FATURAMENTO!$I$8:$I$1048576,DIARIO!C16) -> 0 | E16: =SUMIFS(FATURAMENTO!$H$8:$H$1048576,FATURAMENTO!$M$8:$M$1048576,DIARIO!E$8,FATURAMENTO!$I$8:$I$1048576,C16) -> 0
B17: =TEXT(C17,"dddd") -> sexta-feira | C17: 46031 | D17: =SUMIFS(FATURAMENTO!$H$8:$H$1048576,FATURAMENTO!$M$8:$M$1048576,DIARIO!D$8,FATURAMENTO!$I$8:$I$1048576,DIARIO!C17) -> 0 | E17: =SUMIFS(FATURAMENTO!$H$8:$H$1048576,FATURAMENTO!$M$8:$M$1048576,DIARIO!E$8,FATURAMENTO!$I$8:$I$1048576,C17) -> 0
B18: =TEXT(C18,"dddd") -> sábado | C18: 46032 | D18: =SUMIFS(FATURAMENTO!$H$8:$H$1048576,FATURAMENTO!$M$8:$M$1048576,DIARIO!D$8,FATURAMENTO!$I$8:$I$1048576,DIARIO!C18) -> 0 | E18: =SUMIFS(FATURAMENTO!$H$8:$H$1048576,FATURAMENTO!$M$8:$M$1048576,DIARIO!E$8,FATURAMENTO!$I$8:$I$1048576,C18) -> 0
B19: =TEXT(C19,"dddd") -> domingo | C19: 46033 | D19: =SUMIFS(FATURAMENTO!$H$8:$H$1048576,FATURAMENTO!$M$8:$M$1048576,DIARIO!D$8,FATURAMENTO!$I$8:$I$1048576,DIARIO!C19) -> 0 | E19: =SUMIFS(FATURAMENTO!$H$8:$H$1048576,FATURAMENTO!$M$8:$M$1048576,DIARIO!E$8,FATURAMENTO!$I$8:$I$1048576,C19) -> 0
B20: =TEXT(C20,"dddd") -> segunda-feira | C20: 46034 | D20: =SUMIFS(FATURAMENTO!$H$8:$H$1048576,FATURAMENTO!$M$8:$M$1048576,DIARIO!D$8,FATURAMENTO!$I$8:$I$1048576,DIARIO!C20) -> 0 | E20: =SUMIFS(FATURAMENTO!$H$8:$H$1048576,FATURAMENTO!$M$8:$M$1048576,DIARIO!E$8,FATURAMENTO!$I$8:$I$1048576,C20) -> 0
... B373: =TEXT(C373,"dddd") -> quinta-feira | C373: 46387 | D373: =SUMIFS(FATURAMENTO!$H$8:$H$1048576,FATURAMENTO!$M$8:$M$1048576,DIARIO!D$8,FATURAMENTO!$I$8:$I$1048576,DIARIO!C373) -> 0 | E373: =SUMIFS(FATURAMENTO!$H$8:$H$1048576,FATURAMENTO!$M$8:$M$1048576,DIARIO!E$8,FATURAMENTO!$I$8:$I$1048576,C373) -> 0

Sheet FUNDOS
C5: POSIÇÃO DOS FUNDOS/FIDCS | J5: RECOMPRA | N5: CARTORIO
C6: PARCEIRO | D6: A VENCER | E6: VENCIDO | F6: TOTAL | H6: LIQUIDADO | J6: A RECEBER | K6: RECEBIDO | L6: TOTAL | N6: FUNDO | O6: ALUFORCE
C7: AUGURI | D7: =SUMIFS(FATURAMENTO!$H$8:$H$1048576,FATURAMENTO!$M$8:$M$1048576,FUNDOS!$D$6,FATURAMENTO!$K$8:$K$1048576,FUNDOS!C7) -> 150514.04 | E7: =SUMIFS(FATURAMENTO!$H$8:$H$1048576,FATURAMENTO!$M$8:$M$1048576,$E$6,FATURAMENTO!$K$8:$K$1048576,C7) -> 0 | F7: =D7+E7-L7 -> 150514.04 | H7: =SUMIFS(FATURAMENTO!$H$8:$H$1048576,FATURAMENTO!$M$8:$M$1048576,$H$6,FATURAMENTO!$K$8:$K$1048576,C7) -> 67217.11 | J7: =SUMIFS(FATURAMENTO!$H$8:$H$1048576,FATURAMENTO!$K$8:$K$1048576,FUNDOS!$C7,FATURAMENTO!$Q$8:$Q$1048576,FUNDOS!$J$6) -> 0 | K7: =SUMIFS(FATURAMENTO!$H$8:$H$1048576,FATURAMENTO!$K$8:$K$1048576,FUNDOS!$C7,FATURAMENTO!$Q$8:$Q$1048576,$K$6) -> 0 | L7: =J7 -> 0 | N7: =SUMIFS(FATURAMENTO!$H$8:$H$1048576,FATURAMENTO!$K$8:$K$1048576,FUNDOS!$C7,FATURAMENTO!$S$8:$S$1048576,FUNDOS!$N$6) -> 0 | O7: =SUMIFS(FATURAMENTO!$H$8:$H$1048576,FATURAMENTO!$K$8:$K$1048576,FUNDOS!$C7,FATURAMENTO!$S$8:$S$1048576,$O$6) -> 0
C8: CAPITAL ANNEX | D8: =SUMIFS(FATURAMENTO!$H$8:$H$1048576,FATURAMENTO!$M$8:$M$1048576,FUNDOS!$D$6,FATURAMENTO!$K$8:$K$1048576,FUNDOS!C8) -> 414150.34 | E8: =SUMIFS(FATURAMENTO!$H$8:$H$1048576,FATURAMENTO!$M$8:$M$1048576,$E$6,FATURAMENTO!$K$8:$K$1048576,C8) -> 4381.86 | F8: =D8+E8-L8 -> 418532.2 | H8: =SUMIFS(FATURAMENTO!$H$8:$H$1048576,FATURAMENTO!$M$8:$M$1048576,$H$6,FATURAMENTO!$K$8:$K$1048576,C8) -> 247856.98 | J8: =SUMIFS(FATURAMENTO!$H$8:$H$1048576,FATURAMENTO!$K$8:$K$1048576,FUNDOS!$C8,FATURAMENTO!$Q$8:$Q$1048576,FUNDOS!$J$6) -> 0 | K8: =SUMIFS(FATURAMENTO!$H$8:$H$1048576,FATURAMENTO!$K$8:$K$1048576,FUNDOS!$C8,FATURAMENTO!$Q$8:$Q$1048576,$K$6) -> 0 | L8: =J8 -> 0 | N8: =SUMIFS(FATURAMENTO!$H$8:$H$1048576,FATURAMENTO!$K$8:$K$1048576,FUNDOS!$C8,FATURAMENTO!$S$8:$S$1048576,FUNDOS!$N$6) -> 0 | O8: =SUMIFS(FATURAMENTO!$H$8:$H$1048576,FATURAMENTO!$K$8:$K$1048576,FUNDOS!$C8,FATURAMENTO!$S$8:$S$1048576,$O$6) -> 0
C9: CONTINENTAL | D9: =SUMIFS(FATURAMENTO!$H$8:$H$1048576,FATURAMENTO!$M$8:$M$1048576,FUNDOS!$D$6,FATURAMENTO!$K$8:$K$1048576,FUNDOS!C9) -> 0 | E9: =SUMIFS(FATURAMENTO!$H$8:$H$1048576,FATURAMENTO!$M$8:$M$1048576,$E$6,FATURAMENTO!$K$8:$K$1048576,C9) -> 0 | F9: =D9+E9-L9 -> 0 | H9: =SUMIFS(FATURAMENTO!$H$8:$H$1048576,FATURAMENTO!$M$8:$M$1048576,$H$6,FATURAMENTO!$K$8:$K$1048576,C9) -> 0 | J9: =SUMIFS(FATURAMENTO!$H$8:$H$1048576,FATURAMENTO!$K$8:$K$1048576,FUNDOS!$C9,FATURAMENTO!$Q$8:$Q$1048576,FUNDOS!$J$6) -> 0 | K9: =SUMIFS(FATURAMENTO!$H$8:$H$1048576,FATURAMENTO!$K$8:$K$1048576,FUNDOS!$C9,FATURAMENTO!$Q$8:$Q$1048576,$K$6) -> 0 | L9: =J9 -> 0 | N9: =SUMIFS(FATURAMENTO!$H$8:$H$1048576,FATURAMENTO!$K$8:$K$1048576,FUNDOS!$C9,FATURAMENTO!$S$8:$S$1048576,FUNDOS!$N$6) -> 0 | O9: =SUMIFS(FATURAMENTO!$H$8:$H$1048576,FATURAMENTO!$K$8:$K$1048576,FUNDOS!$C9,FATURAMENTO!$S$8:$S$1048576,$O$6) -> 0
C10: DEL MONTE | D10: =SUMIFS(FATURAMENTO!$H$8:$H$1048576,FATURAMENTO!$M$8:$M$1048576,FUNDOS!$D$6,FATURAMENTO!$K$8:$K$1048576,FUNDOS!C10) -> 4364.1 | E10: =SUMIFS(FATURAMENTO!$H$8:$H$1048576,FATURAMENTO!$M$8:$M$1048576,$E$6,FATURAMENTO!$K$8:$K$1048576,C10) -> 27611 | F10: =D10+E10-L10 -> 31975.1 | H10: =SUMIFS(FATURAMENTO!$H$8:$H$1048576,FATURAMENTO!$M$8:$M$1048576,$H$6,FATURAMENTO!$K$8:$K$1048576,C10) -> 589422.07 | J10: =SUMIFS(FATURAMENTO!$H$8:$H$1048576,FATURAMENTO!$K$8:$K$1048576,FUNDOS!$C10,FATURAMENTO!$Q$8:$Q$1048576,FUNDOS!$J$6) -> 0 | K10: =SUMIFS(FATURAMENTO!$H$8:$H$1048576,FATURAMENTO!$K$8:$K$1048576,FUNDOS!$C10,FATURAMENTO!$Q$8:$Q$1048576,$K$6) -> 0 | L10: =J10 -> 0 | N10: =SUMIFS(FATURAMENTO!$H$8:$H$1048576,FATURAMENTO!$K$8:$K$1048576,FUNDOS!$C10,FATURAMENTO!$S$8:$S$1048576,FUNDOS!$N$6) -> 36494 | O10: =SUMIFS(FATURAMENTO!$H$8:$H$1048576,FATURAMENTO!$K$8:$K$1048576,FUNDOS!$C10,FATURAMENTO!$S$8:$S$1048576,$O$6) -> 0
C11: FAMA | D11: =SUMIFS(FATURAMENTO!$H$8:$H$1048576,FATURAMENTO!$M$8:$M$1048576,FUNDOS!$D$6,FATURAMENTO!$K$8:$K$1048576,FUNDOS!C11) -> 790342.53 | E11: =SUMIFS(FATURAMENTO!$H$8:$H$1048576,FATURAMENTO!$M$8:$M$1048576,$E$6,FATURAMENTO!$K$8:$K$1048576,C11) -> 0 | F11: =D11+E11-L11 -> 790342.53 | H11: =SUMIFS(FATURAMENTO!$H$8:$H$1048576,FATURAMENTO!$M$8:$M$1048576,$H$6,FATURAMENTO!$K$8:$K$1048576,C11) -> 1387214.4 | J11: =SUMIFS(FATURAMENTO!$H$8:$H$1048576,FATURAMENTO!$K$8:$K$1048576,FUNDOS!$C11,FATURAMENTO!$Q$8:$Q$1048576,FUNDOS!$J$6) -> 0 | K11: =SUMIFS(FATURAMENTO!$H$8:$H$1048576,FATURAMENTO!$K$8:$K$1048576,FUNDOS!$C11,FATURAMENTO!$Q$8:$Q$1048576,$K$6) -> 0 | L11: =J11 -> 0 | N11: =SUMIFS(FATURAMENTO!$H$8:$H$1048576,FATURAMENTO!$K$8:$K$1048576,FUNDOS!$C11,FATURAMENTO!$S$8:$S$1048576,FUNDOS!$N$6) -> 38628.76 | O11: =SUMIFS(FATURAMENTO!$H$8:$H$1048576,FATURAMENTO!$K$8:$K$1048576,FUNDOS!$C11,FATURAMENTO!$S$8:$S$1048576,$O$6) -> 0
C12: H8 | D12: =SUMIFS(FATURAMENTO!$H$8:$H$1048576,FATURAMENTO!$M$8:$M$1048576,FUNDOS!$D$6,FATURAMENTO!$K$8:$K$1048576,FUNDOS!C12) -> 404006.17 | E12: =SUMIFS(FATURAMENTO!$H$8:$H$1048576,FATURAMENTO!$M$8:$M$1048576,$E$6,FATURAMENTO!$K$8:$K$1048576,C12) -> 35045.41 | F12: =D12+E12-L12 -> 439051.58 | H12: =SUMIFS(FATURAMENTO!$H$8:$H$1048576,FATURAMENTO!$M$8:$M$1048576,$H$6,FATURAMENTO!$K$8:$K$1048576,C12) -> 380480.24 | J12: =SUMIFS(FATURAMENTO!$H$8:$H$1048576,FATURAMENTO!$K$8:$K$1048576,FUNDOS!$C12,FATURAMENTO!$Q$8:$Q$1048576,FUNDOS!$J$6) -> 0 | K12: =SUMIFS(FATURAMENTO!$H$8:$H$1048576,FATURAMENTO!$K$8:$K$1048576,FUNDOS!$C12,FATURAMENTO!$Q$8:$Q$1048576,$K$6) -> 0 | L12: =J12 -> 0 | N12: =SUMIFS(FATURAMENTO!$H$8:$H$1048576,FATURAMENTO!$K$8:$K$1048576,FUNDOS!$C12,FATURAMENTO!$S$8:$S$1048576,FUNDOS!$N$6) -> 17192 | O12: =SUMIFS(FATURAMENTO!$H$8:$H$1048576,FATURAMENTO!$K$8:$K$1048576,FUNDOS!$C12,FATURAMENTO!$S$8:$S$1048576,$O$6) -> 0
C13: KHAVA | D13: =SUMIFS(FATURAMENTO!$H$8:$H$1048576,FATURAMENTO!$M$8:$M$1048576,FUNDOS!$D$6,FATURAMENTO!$K$8:$K$1048576,FUNDOS!C13) -> 0 | E13: =SUMIFS(FATURAMENTO!$H$8:$H$1048576,FATURAMENTO!$M$8:$M$1048576,$E$6,FATURAMENTO!$K$8:$K$1048576,C13) -> 0 | F13: =D13+E13-L13 -> 0 | H13: =SUMIFS(FATURAMENTO!$H$8:$H$1048576,FATURAMENTO!$M$8:$M$1048576,$H$6,FATURAMENTO!$K$8:$K$1048576,C13) -> 0 | J13: =SUMIFS(FATURAMENTO!$H$8:$H$1048576,FATURAMENTO!$K$8:$K$1048576,FUNDOS!$C13,FATURAMENTO!$Q$8:$Q$1048576,FUNDOS!$J$6) -> 0 | K13: =SUMIFS(FATURAMENTO!$H$8:$H$1048576,FATURAMENTO!$K$8:$K$1048576,FUNDOS!$C13,FATURAMENTO!$Q$8:$Q$1048576,$K$6) -> 0 | L13: =J13 -> 0 | N13: =SUMIFS(FATURAMENTO!$H$8:$H$1048576,FATURAMENTO!$K$8:$K$1048576,FUNDOS!$C13,FATURAMENTO!$S$8:$S$1048576,FUNDOS!$N$6) -> 0 | O13: =SUMIFS(FATURAMENTO!$H$8:$H$1048576,FATURAMENTO!$K$8:$K$1048576,FUNDOS!$C13,FATURAMENTO!$S$8:$S$1048576,$O$6) -> 0
C14: LEPTA | D14: =SUMIFS(FATURAMENTO!$H$8:$H$1048576,FATURAMENTO!$M$8:$M$1048576,FUNDOS!$D$6,FATURAMENTO!$K$8:$K$1048576,FUNDOS!C14) -> 125131.28 | E14: =SUMIFS(FATURAMENTO!$H$8:$H$1048576,FATURAMENTO!$M$8:$M$1048576,$E$6,FATURAMENTO!$K$8:$K$1048576,C14) -> 0 | F14: =D14+E14-L14 -> 125131.28 | H14: =SUMIFS(FATURAMENTO!$H$8:$H$1048576,FATURAMENTO!$M$8:$M$1048576,$H$6,FATURAMENTO!$K$8:$K$1048576,C14) -> 345775 | J14: =SUMIFS(FATURAMENTO!$H$8:$H$1048576,FATURAMENTO!$K$8:$K$1048576,FUNDOS!$C14,FATURAMENTO!$Q$8:$Q$1048576,FUNDOS!$J$6) -> 0 | K14: =SUMIFS(FATURAMENTO!$H$8:$H$1048576,FATURAMENTO!$K$8:$K$1048576,FUNDOS!$C14,FATURAMENTO!$Q$8:$Q$1048576,$K$6) -> 0 | L14: =J14 -> 0 | N14: =SUMIFS(FATURAMENTO!$H$8:$H$1048576,FATURAMENTO!$K$8:$K$1048576,FUNDOS!$C14,FATURAMENTO!$S$8:$S$1048576,FUNDOS!$N$6) -> 0 | O14: =SUMIFS(FATURAMENTO!$H$8:$H$1048576,FATURAMENTO!$K$8:$K$1048576,FUNDOS!$C14,FATURAMENTO!$S$8:$S$1048576,$O$6) -> 0
C15: ONIX | D15: =SUMIFS(FATURAMENTO!$H$8:$H$1048576,FATURAMENTO!$M$8:$M$1048576,FUNDOS!$D$6,FATURAMENTO!$K$8:$K$1048576,FUNDOS!C15) -> 248763.27 | E15: =SUMIFS(FATURAMENTO!$H$8:$H$1048576,FATURAMENTO!$M$8:$M$1048576,$E$6,FATURAMENTO!$K$8:$K$1048576,C15) -> 0 | F15: =D15+E15-L15 -> 248763.27 | H15: =SUMIFS(FATURAMENTO!$H$8:$H$1048576,FATURAMENTO!$M$8:$M$1048576,$H$6,FATURAMENTO!$K$8:$K$1048576,C15) -> 26137.19 | J15: =SUMIFS(FATURAMENTO!$H$8:$H$1048576,FATURAMENTO!$K$8:$K$1048576,FUNDOS!$C15,FATURAMENTO!$Q$8:$Q$1048576,FUNDOS!$J$6) -> 0 | K15: =SUMIFS(FATURAMENTO!$H$8:$H$1048576,FATURAMENTO!$K$8:$K$1048576,FUNDOS!$C15,FATURAMENTO!$Q$8:$Q$1048576,$K$6) -> 0 | L15: =J15 -> 0 | N15: =SUMIFS(FATURAMENTO!$H$8:$H$1048576,FATURAMENTO!$K$8:$K$1048576,FUNDOS!$C15,FATURAMENTO!$S$8:$S$1048576,FUNDOS!$N$6) -> 0 | O15: =SUMIFS(FATURAMENTO!$H$8:$H$1048576,FATURAMENTO!$K$8:$K$1048576,FUNDOS!$C15,FATURAMENTO!$S$8:$S$1048576,$O$6) -> 0
C16: VALE RIO CLARO | D16: =SUMIFS(FATURAMENTO!$H$8:$H$1048576,FATURAMENTO!$M$8:$M$1048576,FUNDOS!$D$6,FATURAMENTO!$K$8:$K$1048576,FUNDOS!C16) -> 33557.59 | E16: =SUMIFS(FATURAMENTO!$H$8:$H$1048576,FATURAMENTO!$M$8:$M$1048576,$E$6,FATURAMENTO!$K$8:$K$1048576,C16) -> 22669.17 | F16: =D16+E16-L16 -> 54893.43 | H16: =SUMIFS(FATURAMENTO!$H$8:$H$1048576,FATURAMENTO!$M$8:$M$1048576,$H$6,FATURAMENTO!$K$8:$K$1048576,C16) -> 361255.92 | J16: =SUMIFS(FATURAMENTO!$H$8:$H$1048576,FATURAMENTO!$K$8:$K$1048576,FUNDOS!$C16,FATURAMENTO!$Q$8:$Q$1048576,FUNDOS!$J$6) -> 1333.33 | K16: =SUMIFS(FATURAMENTO!$H$8:$H$1048576,FATURAMENTO!$K$8:$K$1048576,FUNDOS!$C16,FATURAMENTO!$Q$8:$Q$1048576,$K$6) -> 4540 | L16: =J16 -> 1333.33 | N16: =SUMIFS(FATURAMENTO!$H$8:$H$1048576,FATURAMENTO!$K$8:$K$1048576,FUNDOS!$C16,FATURAMENTO!$S$8:$S$1048576,FUNDOS!$N$6) -> 0 | O16: =SUMIFS(FATURAMENTO!$H$8:$H$1048576,FATURAMENTO!$K$8:$K$1048576,FUNDOS!$C16,FATURAMENTO!$S$8:$S$1048576,$O$6) -> 1333.33
C17: IGNIS | D17: =SUMIFS(FATURAMENTO!$H$8:$H$1048576,FATURAMENTO!$M$8:$M$1048576,FUNDOS!$D$6,FATURAMENTO!$K$8:$K$1048576,FUNDOS!C17) -> 410814.8 | E17: =SUMIFS(FATURAMENTO!$H$8:$H$1048576,FATURAMENTO!$M$8:$M$1048576,$E$6,FATURAMENTO!$K$8:$K$1048576,C17) -> 15986.08 | F17: =D17+E17-L17 -> 426800.88 | H17: =SUMIFS(FATURAMENTO!$H$8:$H$1048576,FATURAMENTO!$M$8:$M$1048576,$H$6,FATURAMENTO!$K$8:$K$1048576,C17) -> 80807.24 | J17: =SUMIFS(FATURAMENTO!$H$8:$H$1048576,FATURAMENTO!$K$8:$K$1048576,FUNDOS!$C17,FATURAMENTO!$Q$8:$Q$1048576,FUNDOS!$J$6) -> 0 | K17: =SUMIFS(FATURAMENTO!$H$8:$H$1048576,FATURAMENTO!$K$8:$K$1048576,FUNDOS!$C17,FATURAMENTO!$Q$8:$Q$1048576,$K$6) -> 7894.96 | L17: =J17 -> 0 | N17: =SUMIFS(FATURAMENTO!$H$8:$H$1048576,FATURAMENTO!$K$8:$K$1048576,FUNDOS!$C17,FATURAMENTO!$S$8:$S$1048576,FUNDOS!$N$6) -> 0 | O17: =SUMIFS(FATURAMENTO!$H$8:$H$1048576,FATURAMENTO!$K$8:$K$1048576,FUNDOS!$C17,FATURAMENTO!$S$8:$S$1048576,$O$6) -> 0
F20: =D20+E20 -> 0 | H20: =SUMIFS(FATURAMENTO!$H$8:$H$1048576,FATURAMENTO!$M$8:$M$1048576,$H$6,FATURAMENTO!$K$8:$K$1048576,C20) -> 0 | L20: =SUMIFS(FATURAMENTO!$H$8:$H$1048576,FATURAMENTO!$Q$8:$Q$1048576,FUNDOS!$L$6,FATURAMENTO!$K$8:$K$1048576,FUNDOS!$C20) -> 0
F21: =D21+E21 -> 0 | H21: =SUMIFS(FATURAMENTO!$H$8:$H$1048576,FATURAMENTO!$M$8:$M$1048576,$H$6,FATURAMENTO!$K$8:$K$1048576,C21) -> 0 | L21: =SUMIFS(FATURAMENTO!$H$8:$H$1048576,FATURAMENTO!$Q$8:$Q$1048576,FUNDOS!$L$6,FATURAMENTO!$K$8:$K$1048576,FUNDOS!$C21) -> 0
D22: =SUM(D7:D16) -> 2170829.3 | E22: =SUM(E7:E16) -> 89707.44 | F22: =SUM(F7:F16) -> 2259203.4 | H22: =SUM(H7:H16) -> 3405359 | J22: =SUM(J7:J21) -> 1333.33 | K22: =SUM(K7:K21) -> 12434.96 | L22: =SUM(L7:L21) -> 1333.33 | N22: =SUM(N7:N21) -> 92314.76 | O22: =SUM(O7:O21) -> 1333.33

Sheet PM
A5: SIMULACAO PRAZO MEDIO
D6: PRAZO MEDIO + | E6: =AVERAGE(Tabela46[PRAZO D+X]) -> 46.857143
A7: DT OPERACAO | B7: 46094 | D7: D + | E7: 3 | H7: CALCULO PM
D8: PM PONDERADO | E8: =IF(ISERROR(SUM(E13:E352)/SUM(B13:B351))=TRUE,0,(SUM(E13:E352)/SUM(B13:B351))) -> 49.968189 | H8: 52.635361
A10: TOTAL BRUTO | B10: =SUM(Tabela46[VALOR]) -> 62369 | D10: QTD. TITULO | E10: =COUNT(B13:B90) -> 21 | H10: SIMULACAO TAXA ACORDADA | K10: TAXA ACORDADA
A12: DT VENCIMENTO | B12: VALOR | C12: PRAZO NOMINAL | D12: PRAZO D+X | E12: PR X VALOR | H12: INSTITUIÇÃO | I12: VALE RIO CLARO | K12: CÓDIGO | L12: INSTITUICAO | M12: TIPO OPERACAO | N12: TIPO INSTITUICAO | O12: TAXA ACORDADA | P12: TAR DE COB | Q12: REEMB TED / TRANSF | R12: ANALISE E CONTRATO | S12: REEMB ASSINAT DIG | T12: REEMB SERASA | U12: TAC
A13: 46121 | B13: 1878 | C13: =IF(A13="","",A13-$B$7) -> 27 | D13: =IF(A13="","",IF($B$7="","",IF(OR(WEEKDAY(A13)=5,WEEKDAY(A13)=6,WEEKDAY(A13)=7),A13-$B$7+$E$7+2,IF(WEEKDAY(A13)=1,A13-$B$7+$E$7+1,A13-$B$7+$E$7)))) -> 32 | E13: =IF(D13="","",IF(B13="","",IF(A13="","",IF($B$7="","",(D13*B13))))) -> 60096 | H13: TIPO OPERAÇÃO | I13: BOLETO | K13: =IFERROR(CONCATENATE(Tabela3[[#This Row],[INSTITUICAO]]," ",Tabela3[[#This Row],[TIPO OPERACAO]]," ",Tabela3[[#This Row],[TIPO INSTITUICAO]])," ") -> OLAM BOLETO FIDC | L13: OLAM | M13: BOLETO | N13: FIDC | O13: 0.023
A14: 46128 | B14: 1368 | C14: =IF(A14="","",A14-$B$7) -> 34 | D14: =IF(A14="","",IF($B$7="","",IF(OR(WEEKDAY(A14)=5,WEEKDAY(A14)=6,WEEKDAY(A14)=7),A14-$B$7+$E$7+2,IF(WEEKDAY(A14)=1,A14-$B$7+$E$7+1,A14-$B$7+$E$7)))) -> 39 | E14: =IF(D14="","",IF(B14="","",IF(A14="","",IF($B$7="","",(D14*B14))))) -> 53352 | H14: TIPO INSTITUICAO | I14: FIDC | K14: =IFERROR(CONCATENATE(Tabela3[[#This Row],[INSTITUICAO]]," ",Tabela3[[#This Row],[TIPO OPERACAO]]," ",Tabela3[[#This Row],[TIPO INSTITUICAO]])," ") -> RDF BOLETO FIDC | L14: RDF | M14: BOLETO | N14: FIDC | O14: 0.0175
A15: 46135 | B15: 1368 | C15: =IF(A15="","",A15-$B$7) -> 41 | D15: =IF(A15="","",IF($B$7="","",IF(OR(WEEKDAY(A15)=5,WEEKDAY(A15)=6,WEEKDAY(A15)=7),A15-$B$7+$E$7+2,IF(WEEKDAY(A15)=1,A15-$B$7+$E$7+1,A15-$B$7+$E$7)))) -> 46 | E15: =IF(D15="","",IF(B15="","",IF(A15="","",IF($B$7="","",(D15*B15))))) -> 62928 | H15: TAXA ACORDADA | I15: 0.0403 | K15: =IFERROR(CONCATENATE(Tabela3[[#This Row],[INSTITUICAO]]," ",Tabela3[[#This Row],[TIPO OPERACAO]]," ",Tabela3[[#This Row],[TIPO INSTITUICAO]])," ") -> ACREDITAR BOLETO FIDC | L15: ACREDITAR | M15: BOLETO | N15: FIDC | O15: 0.025
A16: 46142 | B16: 1368 | C16: =IF(A16="","",A16-$B$7) -> 48 | D16: =IF(A16="","",IF($B$7="","",IF(OR(WEEKDAY(A16)=5,WEEKDAY(A16)=6,WEEKDAY(A16)=7),A16-$B$7+$E$7+2,IF(WEEKDAY(A16)=1,A16-$B$7+$E$7+1,A16-$B$7+$E$7)))) -> 53 | E16: =IF(D16="","",IF(B16="","",IF(A16="","",IF($B$7="","",(D16*B16))))) -> 72504 | H16: PRAZO MEDIO | I16: =E8 -> 49.968189 | K16: =IFERROR(CONCATENATE(Tabela3[[#This Row],[INSTITUICAO]]," ",Tabela3[[#This Row],[TIPO OPERACAO]]," ",Tabela3[[#This Row],[TIPO INSTITUICAO]])," ") -> KREDITARE BOLETO FIDC | L16: KREDITARE | M16: BOLETO | N16: FIDC | O16: 0.022
A17: 46121 | B17: 1368 | C17: =IF(A17="","",A17-$B$7) -> 27 | D17: =IF(A17="","",IF($B$7="","",IF(OR(WEEKDAY(A17)=5,WEEKDAY(A17)=6,WEEKDAY(A17)=7),A17-$B$7+$E$7+2,IF(WEEKDAY(A17)=1,A17-$B$7+$E$7+1,A17-$B$7+$E$7)))) -> 32 | E17: =IF(D17="","",IF(B17="","",IF(A17="","",IF($B$7="","",(D17*B17))))) -> 43776 | H17: VALOR BRUTO | I17: =B10 -> 62369 | K17: =IFERROR(CONCATENATE(Tabela3[[#This Row],[INSTITUICAO]]," ",Tabela3[[#This Row],[TIPO OPERACAO]]," ",Tabela3[[#This Row],[TIPO INSTITUICAO]])," ") -> ASIA BOLETO FIDC | L17: ASIA | M17: BOLETO | N17: FIDC | O17: 0.018
A18: 46128 | B18: 1368 | C18: =IF(A18="","",A18-$B$7) -> 34 | D18: =IF(A18="","",IF($B$7="","",IF(OR(WEEKDAY(A18)=5,WEEKDAY(A18)=6,WEEKDAY(A18)=7),A18-$B$7+$E$7+2,IF(WEEKDAY(A18)=1,A18-$B$7+$E$7+1,A18-$B$7+$E$7)))) -> 39 | E18: =IF(D18="","",IF(B18="","",IF(A18="","",IF($B$7="","",(D18*B18))))) -> 53352 | H18: VALOR LIQUIDO | I18: 44675.69 | K18: =IFERROR(CONCATENATE(Tabela3[[#This Row],[INSTITUICAO]]," ",Tabela3[[#This Row],[TIPO OPERACAO]]," ",Tabela3[[#This Row],[TIPO INSTITUICAO]])," ") -> MOKA FOMENTO FIDC | L18: MOKA | M18: FOMENTO | N18: FIDC | O18: 0.031
A19: 46135 | B19: 1368 | C19: =IF(A19="","",A19-$B$7) -> 41 | D19: =IF(A19="","",IF($B$7="","",IF(OR(WEEKDAY(A19)=5,WEEKDAY(A19)=6,WEEKDAY(A19)=7),A19-$B$7+$E$7+2,IF(WEEKDAY(A19)=1,A19-$B$7+$E$7+1,A19-$B$7+$E$7)))) -> 46 | E19: =IF(D19="","",IF(B19="","",IF(A19="","",IF($B$7="","",(D19*B19))))) -> 62928 | H19: JUROS | I19: =I17-I18 -> 17693.31 | K19: =IFERROR(CONCATENATE(Tabela3[[#This Row],[INSTITUICAO]]," ",Tabela3[[#This Row],[TIPO OPERACAO]]," ",Tabela3[[#This Row],[TIPO INSTITUICAO]])," ") -> KREDITARE CHEQUE FIDC | L19: KREDITARE | M19: CHEQUE | N19: FIDC | O19: 0.025
A20: 46142 | B20: 1368 | C20: =IF(A20="","",A20-$B$7) -> 48 | D20: =IF(A20="","",IF($B$7="","",IF(OR(WEEKDAY(A20)=5,WEEKDAY(A20)=6,WEEKDAY(A20)=7),A20-$B$7+$E$7+2,IF(WEEKDAY(A20)=1,A20-$B$7+$E$7+1,A20-$B$7+$E$7)))) -> 53 | E20: =IF(D20="","",IF(B20="","",IF(A20="","",IF($B$7="","",(D20*B20))))) -> 72504 | H20: MULTA | I20: 0 | K20: =IFERROR(CONCATENATE(Tabela3[[#This Row],[INSTITUICAO]]," ",Tabela3[[#This Row],[TIPO OPERACAO]]," ",Tabela3[[#This Row],[TIPO INSTITUICAO]])," ") -> VIP BOLETO FACT | L20: VIP | M20: BOLETO | N20: FACT | O20: 0.018
A21: 46127 | B21: 1108 | C21: =IF(A21="","",A21-$B$7) -> 33 | D21: =IF(A21="","",IF($B$7="","",IF(OR(WEEKDAY(A21)=5,WEEKDAY(A21)=6,WEEKDAY(A21)=7),A21-$B$7+$E$7+2,IF(WEEKDAY(A21)=1,A21-$B$7+$E$7+1,A21-$B$7+$E$7)))) -> 36 | E21: =IF(D21="","",IF(B21="","",IF(A21="","",IF($B$7="","",(D21*B21))))) -> 39888 | H21: VALOR MULTA | I21: =I20*I17 -> 0 | K21: =IFERROR(CONCATENATE(Tabela3[[#This Row],[INSTITUICAO]]," ",Tabela3[[#This Row],[TIPO OPERACAO]]," ",Tabela3[[#This Row],[TIPO INSTITUICAO]])," ") -> LANA BOLETO FIDC | L21: LANA | M21: BOLETO | N21: FIDC | O21: 0.019
A22: 46142 | B22: 1108 | C22: =IF(A22="","",A22-$B$7) -> 48 | D22: =IF(A22="","",IF($B$7="","",IF(OR(WEEKDAY(A22)=5,WEEKDAY(A22)=6,WEEKDAY(A22)=7),A22-$B$7+$E$7+2,IF(WEEKDAY(A22)=1,A22-$B$7+$E$7+1,A22-$B$7+$E$7)))) -> 53 | E22: =IF(D22="","",IF(B22="","",IF(A22="","",IF($B$7="","",(D22*B22))))) -> 58724 | H22: TOTAL | I22: =SUM(I19:I20) -> 17693.31 | K22: =IFERROR(CONCATENATE(Tabela3[[#This Row],[INSTITUICAO]]," ",Tabela3[[#This Row],[TIPO OPERACAO]]," ",Tabela3[[#This Row],[TIPO INSTITUICAO]])," ") -> IOSAN BOLETO FIDC | L22: IOSAN | M22: BOLETO | N22: FIDC | O22: 0.023
A23: 46157 | B23: 9972 | C23: =IF(A23="","",A23-$B$7) -> 63 | D23: =IF(A23="","",IF($B$7="","",IF(OR(WEEKDAY(A23)=5,WEEKDAY(A23)=6,WEEKDAY(A23)=7),A23-$B$7+$E$7+2,IF(WEEKDAY(A23)=1,A23-$B$7+$E$7+1,A23-$B$7+$E$7)))) -> 68 | E23: =IF(D23="","",IF(B23="","",IF(A23="","",IF($B$7="","",(D23*B23))))) -> 678096 | K23: =IFERROR(CONCATENATE(Tabela3[[#This Row],[INSTITUICAO]]," ",Tabela3[[#This Row],[TIPO OPERACAO]]," ",Tabela3[[#This Row],[TIPO INSTITUICAO]])," ") -> ACTIVA BOLETO FIDC | L23: ACTIVA | M23: BOLETO | N23: FIDC | O23: 0.023
A24: 46127 | B24: 9972 | C24: =IF(A24="","",A24-$B$7) -> 33 | D24: =IF(A24="","",IF($B$7="","",IF(OR(WEEKDAY(A24)=5,WEEKDAY(A24)=6,WEEKDAY(A24)=7),A24-$B$7+$E$7+2,IF(WEEKDAY(A24)=1,A24-$B$7+$E$7+1,A24-$B$7+$E$7)))) -> 36 | E24: =IF(D24="","",IF(B24="","",IF(A24="","",IF($B$7="","",(D24*B24))))) -> 358992 | H24: LIQ. OPERAÇÃO | I24: 0 | K24: =IFERROR(CONCATENATE(Tabela3[[#This Row],[INSTITUICAO]]," ",Tabela3[[#This Row],[TIPO OPERACAO]]," ",Tabela3[[#This Row],[TIPO INSTITUICAO]])," ") -> GENEBRA BOLETO FIDC | L24: GENEBRA | M24: BOLETO | N24: FIDC
A25: 46142 | B25: 9972 | C25: =IF(A25="","",A25-$B$7) -> 48 | D25: =IF(A25="","",IF($B$7="","",IF(OR(WEEKDAY(A25)=5,WEEKDAY(A25)=6,WEEKDAY(A25)=7),A25-$B$7+$E$7+2,IF(WEEKDAY(A25)=1,A25-$B$7+$E$7+1,A25-$B$7+$E$7)))) -> 53 | E25: =IF(D25="","",IF(B25="","",IF(A25="","",IF($B$7="","",(D25*B25))))) -> 528516 | H25: TOTAL DEDUÇÕES | I25: =I17-I24 -> 62369 | K25: =IFERROR(CONCATENATE(Tabela3[[#This Row],[INSTITUICAO]]," ",Tabela3[[#This Row],[TIPO OPERACAO]]," ",Tabela3[[#This Row],[TIPO INSTITUICAO]])," ") -> DEL MONTE BOLETO FIDC | L25: DEL MONTE | M25: BOLETO | N25: FIDC | O25: 0.021
A26: 46157 | B26: 3413 | C26: =IF(A26="","",A26-$B$7) -> 63 | D26: =IF(A26="","",IF($B$7="","",IF(OR(WEEKDAY(A26)=5,WEEKDAY(A26)=6,WEEKDAY(A26)=7),A26-$B$7+$E$7+2,IF(WEEKDAY(A26)=1,A26-$B$7+$E$7+1,A26-$B$7+$E$7)))) -> 68 | E26: =IF(D26="","",IF(B26="","",IF(A26="","",IF($B$7="","",(D26*B26))))) -> 232084 | H26: TAXA COBRADA | I26: =I25/I17/I16*30 -> 0.60038197 | K26: =IFERROR(CONCATENATE(Tabela3[[#This Row],[INSTITUICAO]]," ",Tabela3[[#This Row],[TIPO OPERACAO]]," ",Tabela3[[#This Row],[TIPO INSTITUICAO]])," ") -> DEL MONTE COMISSARIA FIDC | L26: DEL MONTE | M26: COMISSARIA | N26: FIDC | O26: 0.028
A27: 46126 | B27: 2377 | C27: =IF(A27="","",A27-$B$7) -> 32 | D27: =IF(A27="","",IF($B$7="","",IF(OR(WEEKDAY(A27)=5,WEEKDAY(A27)=6,WEEKDAY(A27)=7),A27-$B$7+$E$7+2,IF(WEEKDAY(A27)=1,A27-$B$7+$E$7+1,A27-$B$7+$E$7)))) -> 35 | E27: =IF(D27="","",IF(B27="","",IF(A27="","",IF($B$7="","",(D27*B27))))) -> 83195 | H27: DIFERENCA | I27: =I18-(I17-I25) -> 44675.69 | K27: =IFERROR(CONCATENATE(Tabela3[[#This Row],[INSTITUICAO]]," ",Tabela3[[#This Row],[TIPO OPERACAO]]," ",Tabela3[[#This Row],[TIPO INSTITUICAO]])," ") -> SQUARE BOLETO FIDC | L27: SQUARE | M27: BOLETO | N27: FIDC | O27: 0.0255
A28: 46140 | B28: 2377 | C28: =IF(A28="","",A28-$B$7) -> 46 | D28: =IF(A28="","",IF($B$7="","",IF(OR(WEEKDAY(A28)=5,WEEKDAY(A28)=6,WEEKDAY(A28)=7),A28-$B$7+$E$7+2,IF(WEEKDAY(A28)=1,A28-$B$7+$E$7+1,A28-$B$7+$E$7)))) -> 49 | E28: =IF(D28="","",IF(B28="","",IF(A28="","",IF($B$7="","",(D28*B28))))) -> 116473 | H28: DIFERENCA % | I28: =I26-I15 -> 0.56008197 | K28: =IFERROR(CONCATENATE(Tabela3[[#This Row],[INSTITUICAO]]," ",Tabela3[[#This Row],[TIPO OPERACAO]]," ",Tabela3[[#This Row],[TIPO INSTITUICAO]])," ") -> SOMA BOLETO FIDC | L28: SOMA | M28: BOLETO | N28: FIDC | O28: 0.018
